Workbook
Name 古神道: '古神道'!$A$24:$A$43
Name 武鬥家: '武鬥家'!$A$24:$A$59
Name 風水士: '風水士'!$A$24:$A$51
Name 異端: '異端'!$A$24:$A$48
Name 劍士: '劍士'!$A$24:$A$61
Name 忍者: '忍者'!$A$24:$A$41
Name 風格: '風格'!$A$1:$A$34
Name 魔術師: '魔術師'!$A$24:$A$73
Name 狩人: '狩人'!$A$24:$A$72
Name 感情: '感情'!$A$1:$A$49
Name 策士: '策士'!$A$24:$A$48
Name 無名劍: '無名劍'!$A$24:$A$46
Name 左道: '左道'!$A$24:$A$53
Name 代行者: '代行者'!$A$24:$A$61
Name 超能力者: '超能力者'!$A$26:$A$55
Name 狩獵者: '狩獵者'!$A$24:$A$68
Name NamedRange1: '角色卡'!$B$10:$D$10

Sheet 角色卡
A1: 個人資料
A2: 姓名 | K2: 戰鬥數值
A3: 玩家名稱 | K3: 【能力名】 | L3: 基礎 | M3: 級別1修正 | N3: 級別2修正 | O3: 級別3修正 | P3: 特殊 | Q3: 合計
A4: 種族 | F4: 地域社會 | K4: 【近戰】 | L4: =INT(J9+J10) -> 0 | M4: {=IF(AND($D$7<>"",$E$7<>0),VLOOKUP(K4,INDIRECT($D$7&"!$A$7:$K$14"),'角色卡'!$E$7+1,FALSE),0)} -> 0 | N4: {=IF(AND($D$8<>"",$E$8<>0),VLOOKUP(K4,INDIRECT($D$8&"!$A$7:$K$14"),'角色卡'!$E$8+1,FALSE),0)} -> 0 | O4: {=IF(AND($D$9<>"",$E$9<>0),VLOOKUP(K4,INDIRECT($D$9&"!$A$7:$K$14"),'角色卡'!$E$9+1,FALSE),0)} -> 0 | Q4: =SUM(L4:P4) -> 0
A5: 年齢 | C5: 性別 | F5: 外貌(髪/瞳/肌/身) | K5: 【射撃】 | L5: =INT(J10+J11) -> 0 | M5: {=IF(AND($D$7<>"",$E$7<>0),VLOOKUP(K5,INDIRECT($D$7&"!$A$7:$K$14"),'角色卡'!$E$7+1,FALSE),0)} -> 0 | N5: {=IF(AND($D$8<>"",$E$8<>0),VLOOKUP(K5,INDIRECT($D$8&"!$A$7:$K$14"),'角色卡'!$E$8+1,FALSE),0)} -> 0 | O5: {=IF(AND($D$9<>"",$E$9<>0),VLOOKUP(K5,INDIRECT($D$9&"!$A$7:$K$14"),'角色卡'!$E$9+1,FALSE),0)} -> 0 | Q5: =SUM(L5:P5) -> 0
B6: 初始級別 | C6: 初始等級 | D6: 級別 | E6: 級別等級 | K6: 【精神】 | L6: =INT(J11+J12) -> 0 | M6: {=IF(AND($D$7<>"",$E$7<>0),VLOOKUP(K6,INDIRECT($D$7&"!$A$7:$K$14"),'角色卡'!$E$7+1,FALSE),0)} -> 0 | N6: {=IF(AND($D$8<>"",$E$8<>0),VLOOKUP(K6,INDIRECT($D$8&"!$A$7:$K$14"),'角色卡'!$E$8+1,FALSE),0)} -> 0 | O6: {=IF(AND($D$9<>"",$E$9<>0),VLOOKUP(K6,INDIRECT($D$9&"!$A$7:$K$14"),'角色卡'!$E$9+1,FALSE),0)} -> 0 | Q6: =SUM(L6:P6) -> 0
A7: 級別1 | B7: 狩人 | D7: =IF(B7<>"",B7,"") -> 狩人 | F7: 角色等級 | H7: 剩餘經驗點 | K7: 【行動】 | L7: =INT(J9+J12) -> 0 | M7: {=IF(AND($D$7<>"",$E$7<>0),VLOOKUP(K7,INDIRECT($D$7&"!$A$7:$K$14"),'角色卡'!$E$7+1,FALSE),0)} -> 0 | N7: {=IF(AND($D$8<>"",$E$8<>0),VLOOKUP(K7,INDIRECT($D$8&"!$A$7:$K$14"),'角色卡'!$E$8+1,FALSE),0)} -> 0 | O7: {=IF(AND($D$9<>"",$E$9<>0),VLOOKUP(K7,INDIRECT($D$9&"!$A$7:$K$14"),'角色卡'!$E$9+1,FALSE),0)} -> 0 | Q7: =SUM(L7:P7) -> 0
A8: 級別2 | F8: 基本能力値 | H8: (初始紅利1) | K8: 【生命力】 | L8: =IF(G7>5,INT(J9+J11)*G7,INT(J9+J11)*5) -> 0 | M8: {=IF(AND($D$7<>"",$E$7<>0),VLOOKUP(K8,INDIRECT($D$7&"!$A$7:$K$14"),'角色卡'!$E$7+1,FALSE),0)} -> 0 | N8: {=IF(AND($D$8<>"",$E$8<>0),VLOOKUP(K8,INDIRECT($D$8&"!$A$7:$K$14"),'角色卡'!$E$8+1,FALSE),0)} -> 0 | O8: {=IF(AND($D$9<>"",$E$9<>0),VLOOKUP(K8,INDIRECT($D$9&"!$A$7:$K$14"),'角色卡'!$E$9+1,FALSE),0)} -> 0 | Q8: =SUM(L8:P8) -> 0
A9: 級別3 | D9: =IF(B9<>"",B9,"") | F9: 體力 | G9: {=IF(AND($B$7<>"",$C$7<>0),INDIRECT('角色卡'!$B$7&"!$A$4")*'角色卡'!$C$7,0)+IF(AND($B$8<>"",$C$8<>0),INDIRECT('角色卡'!$B$8&"!$A$4")*'角色卡'!$C$8,0)+IF(AND($B$9<>"",$C$9<>0),INDIRECT('角色卡'!$B$9&"!$A$4")*'角色卡'!$C$9,0)+H9} -> 0 | I9: 【體力】 | J9: =INT(G9/3) -> 0 | K9: 【集中力】 | L9: =INT(J10+J12)*5 -> 0 | M9: {=IF(AND($D$7<>"",$E$7<>0),VLOOKUP(K9,INDIRECT($D$7&"!$A$7:$K$14"),'角色卡'!$E$7+1,FALSE),0)} -> 0 | N9: {=IF(AND($D$8<>"",$E$8<>0),VLOOKUP(K9,INDIRECT($D$8&"!$A$7:$K$14"),'角色卡'!$E$8+1,FALSE),0)} -> 0 | O9: {=IF(AND($D$9<>"",$E$9<>0),VLOOKUP(K9,INDIRECT($D$9&"!$A$7:$K$14"),'角色卡'!$E$9+1,FALSE),0)} -> 0 | Q9: =SUM(L9:P9) -> 0
A10: 風格 | E10: 分類 | F10: 知覺 | G10: {=IF(AND($B$7<>"",$C$7<>0),INDIRECT('角色卡'!$B$7&"!$B$4")*'角色卡'!$C$7,0)+IF(AND($B$8<>"",$C$8<>0),INDIRECT('角色卡'!$B$8&"!$B$4")*'角色卡'!$C$8,0)+IF(AND($B$9<>"",$C$9<>0),INDIRECT('角色卡'!$B$9&"!$B$4")*'角色卡'!$C$9,0)+H10} -> 0 | I10: 【知覺】 | J10: =INT(G10/3) -> 0 | K10: 【防御點】 | L10: 0 | M10: {=IF(AND($D$7<>"",$E$7<>0),VLOOKUP(K10,INDIRECT($D$7&"!$A$7:$K$14"),'角色卡'!$E$7+1,FALSE),0)} -> 0 | N10: {=IF(AND($D$8<>"",$E$8<>0),VLOOKUP(K10,INDIRECT($D$8&"!$A$7:$K$14"),'角色卡'!$E$8+1,FALSE),0)} -> 0 | O10: {=IF(AND($D$9<>"",$E$9<>0),VLOOKUP(K10,INDIRECT($D$9&"!$A$7:$K$14"),'角色卡'!$E$9+1,FALSE),0)} -> 0 | Q10: =SUM(L10:P10) -> 0
A11: 背反律 | B11: =IF(AND($B$10<>"風格",$B$10<>""),VLOOKUP($B$10,'風格'!$A$2:$K$35,3,FALSE),"") | E11: =IF(AND($B$10<>"風格",$B$10<>""),VLOOKUP($B$10,'風格'!$A$2:$K$34,4,FALSE),"") | F11: 理智 | G11: {=IF(AND($B$7<>"",$C$7<>0),INDIRECT('角色卡'!$B$7&"!$C$4")*'角色卡'!$C$7,0)+IF(AND($B$8<>"",$C$8<>0),INDIRECT('角色卡'!$B$8&"!$C$4")*'角色卡'!$C$8,0)+IF(AND($B$9<>"",$C$9<>0),INDIRECT('角色卡'!$B$9&"!$C$4")*'角色卡'!$C$9,0)+H11} -> 0 | I11: 【理智】 | J11: =INT(G11/3) -> 0 | K11: 屬性値 | M11: 火 | O11: 水
A12: 代償 | B12: =IF(AND($B$10<>"風格",$B$10<>""),VLOOKUP($B$10,'風格'!$A$2:$K$35,5,FALSE),"") | F12: 意志 | G12: {=IF(AND($B$7<>"",$C$7<>0),INDIRECT('角色卡'!$B$7&"!$D$4")*'角色卡'!$C$7,0)+IF(AND($B$8<>"",$C$8<>0),INDIRECT('角色卡'!$B$8&"!$D$4")*'角色卡'!$C$8,0)+IF(AND($B$9<>"",$C$9<>0),INDIRECT('角色卡'!$B$9&"!$D$4")*'角色卡'!$C$9,0)+H12} -> 0 | I12: 【意志】 | J12: =INT(G12/3) -> 0 | K12: 地 | M12: 風 | O12: 空 | P12: 6
A13: 獲得感情 | B13: =IF(AND($B$10<>"風格",$B$10<>""),VLOOKUP($B$10,'風格'!$A$2:$K$35,7,FALSE),"") | E13: 效果 | F13: =IF(AND($B$10<>"風格",$B$10<>""),VLOOKUP($B$10,'風格'!$A$2:$K$35,9,FALSE),"")
A14: 二段條件 | B14: =IF(AND($B$10<>"風格",$B$10<>""),VLOOKUP($B$10,'風格'!$A$2:$K$35,10,FALSE),"") | E14: 追加效果 | F14: =IF(AND($B$10<>"風格",$B$10<>""),VLOOKUP($B$10,'風格'!$A$2:$K$35,11,FALSE),"")
A15: 特技
A16: 級別 | B16: 技能名稱 | D16: 分類 | E16: 代價 | F16: 情緒獎勵 | G16: 效果
A17: 狩人 | B17: 弓掌握 | D17: =IF(AND($A17<>"",$B17<>""),VLOOKUP($B17,INDIRECT($A17&"!A26:F75"),2,FALSE),"") -> 攻擊類型／射擊 | E17: =IF(AND($A17<>"",$B17<>""),VLOOKUP($B17,INDIRECT($A17&"!A26:F75"),3,FALSE),"") -> 待機延遲2 | F17: =IF(AND($A17<>"",$B17<>""),VLOOKUP($B17,INDIRECT($A17&"!A26:F75"),4,FALSE),"") -> 待機總合／2 | G17: =IF(AND($A17<>"",$B17<>""),VLOOKUP($B17,INDIRECT($A17&"!A26:F75"),6,FALSE),"") -> 造成２Ｄ６+《體力》點傷害；每追加一回《４》點待機延遲，《》內的體力倍率+１且命中得到+１獎勵。
D18: =IF(AND($A18<>"",$B18<>""),VLOOKUP($B18,INDIRECT($A18&"!A26:F75"),2,FALSE),"") | E18: =IF(AND($A18<>"",$B18<>""),VLOOKUP($B18,INDIRECT($A18&"!A26:F75"),3,FALSE),"") | F18: =IF(AND($A18<>"",$B18<>""),VLOOKUP($B18,INDIRECT($A18&"!A26:F75"),4,FALSE),"") | G18: =IF(AND($A18<>"",$B18<>""),VLOOKUP($B18,INDIRECT($A18&"!A26:F75"),6,FALSE),"")
D19: =IF(AND($A19<>"",$B19<>""),VLOOKUP($B19,INDIRECT($A19&"!A26:F75"),2,FALSE),"") | E19: =IF(AND($A19<>"",$B19<>""),VLOOKUP($B19,INDIRECT($A19&"!A26:F75"),3,FALSE),"") | F19: =IF(AND($A19<>"",$B19<>""),VLOOKUP($B19,INDIRECT($A19&"!A26:F75"),4,FALSE),"") | G19: =IF(AND($A19<>"",$B19<>""),VLOOKUP($B19,INDIRECT($A19&"!A26:F75"),6,FALSE),"")
D20: =IF(AND($A20<>"",$B20<>""),VLOOKUP($B20,INDIRECT($A20&"!A26:F75"),2,FALSE),"") | E20: =IF(AND($A20<>"",$B20<>""),VLOOKUP($B20,INDIRECT($A20&"!A26:F75"),3,FALSE),"") | F20: =IF(AND($A20<>"",$B20<>""),VLOOKUP($B20,INDIRECT($A20&"!A26:F75"),4,FALSE),"") | G20: =IF(AND($A20<>"",$B20<>""),VLOOKUP($B20,INDIRECT($A20&"!A26:F75"),6,FALSE),"")
D21: =IF(AND($A21<>"",$B21<>""),VLOOKUP($B21,INDIRECT($A21&"!A26:F75"),2,FALSE),"") | E21: =IF(AND($A21<>"",$B21<>""),VLOOKUP($B21,INDIRECT($A21&"!A26:F75"),3,FALSE),"") | F21: =IF(AND($A21<>"",$B21<>""),VLOOKUP($B21,INDIRECT($A21&"!A26:F75"),4,FALSE),"") | G21: =IF(AND($A21<>"",$B21<>""),VLOOKUP($B21,INDIRECT($A21&"!A26:F75"),6,FALSE),"")
D22: =IF(AND($A22<>"",$B22<>""),VLOOKUP($B22,INDIRECT($A22&"!A26:F75"),2,FALSE),"") | E22: =IF(AND($A22<>"",$B22<>""),VLOOKUP($B22,INDIRECT($A22&"!A26:F75"),3,FALSE),"") | F22: =IF(AND($A22<>"",$B22<>""),VLOOKUP($B22,INDIRECT($A22&"!A26:F75"),4,FALSE),"") | G22: =IF(AND($A22<>"",$B22<>""),VLOOKUP($B22,INDIRECT($A22&"!A26:F75"),6,FALSE),"")
D23: =IF(AND($A23<>"",$B23<>""),VLOOKUP($B23,INDIRECT($A23&"!A26:F75"),2,FALSE),"") | E23: =IF(AND($A23<>"",$B23<>""),VLOOKUP($B23,INDIRECT($A23&"!A26:F75"),3,FALSE),"") | F23: =IF(AND($A23<>"",$B23<>""),VLOOKUP($B23,INDIRECT($A23&"!A26:F75"),4,FALSE),"") | G23: =IF(AND($A23<>"",$B23<>""),VLOOKUP($B23,INDIRECT($A23&"!A26:F75"),6,FALSE),"")
D24: =IF(AND($A24<>"",$B24<>""),VLOOKUP($B24,INDIRECT($A24&"!A26:F75"),2,FALSE),"") | E24: =IF(AND($A24<>"",$B24<>""),VLOOKUP($B24,INDIRECT($A24&"!A26:F75"),3,FALSE),"") | F24: =IF(AND($A24<>"",$B24<>""),VLOOKUP($B24,INDIRECT($A24&"!A26:F75"),4,FALSE),"") | G24: =IF(AND($A24<>"",$B24<>""),VLOOKUP($B24,INDIRECT($A24&"!A26:F75"),6,FALSE),"")
D25: =IF(AND($A25<>"",$B25<>""),VLOOKUP($B25,INDIRECT($A25&"!A26:F75"),2,FALSE),"") | E25: =IF(AND($A25<>"",$B25<>""),VLOOKUP($B25,INDIRECT($A25&"!A26:F75"),3,FALSE),"") | F25: =IF(AND($A25<>"",$B25<>""),VLOOKUP($B25,INDIRECT($A25&"!A26:F75"),4,FALSE),"") | G25: =IF(AND($A25<>"",$B25<>""),VLOOKUP($B25,INDIRECT($A25&"!A26:F75"),6,FALSE),"")
D26: =IF(AND($A26<>"",$B26<>""),VLOOKUP($B26,INDIRECT($A26&"!A26:F75"),2,FALSE),"") | E26: =IF(AND($A26<>"",$B26<>""),VLOOKUP($B26,INDIRECT($A26&"!A26:F75"),3,FALSE),"") | F26: =IF(AND($A26<>"",$B26<>""),VLOOKUP($B26,INDIRECT($A26&"!A26:F75"),4,FALSE),"") | G26: =IF(AND($A26<>"",$B26<>""),VLOOKUP($B26,INDIRECT($A26&"!A26:F75"),6,FALSE),"")
D27: =IF(AND($A27<>"",$B27<>""),VLOOKUP($B27,INDIRECT($A27&"!A26:F75"),2,FALSE),"") | E27: =IF(AND($A27<>"",$B27<>""),VLOOKUP($B27,INDIRECT($A27&"!A26:F75"),3,FALSE),"") | F27: =IF(AND($A27<>"",$B27<>""),VLOOKUP($B27,INDIRECT($A27&"!A26:F75"),4,FALSE),"") | G27: =IF(AND($A27<>"",$B27<>""),VLOOKUP($B27,INDIRECT($A27&"!A26:F75"),6,FALSE),"")
D28: =IF(AND($A28<>"",$B28<>""),VLOOKUP($B28,INDIRECT($A28&"!A26:F75"),2,FALSE),"") | E28: =IF(AND($A28<>"",$B28<>""),VLOOKUP($B28,INDIRECT($A28&"!A26:F75"),3,FALSE),"") | F28: =IF(AND($A28<>"",$B28<>""),VLOOKUP($B28,INDIRECT($A28&"!A26:F75"),4,FALSE),"") | G28: =IF(AND($A28<>"",$B28<>""),VLOOKUP($B28,INDIRECT($A28&"!A26:F75"),6,FALSE),"")
D29: =IF(AND($A29<>"",$B29<>""),VLOOKUP($B29,INDIRECT($A29&"!A26:F75"),2,FALSE),"") | E29: =IF(AND($A29<>"",$B29<>""),VLOOKUP($B29,INDIRECT($A29&"!A26:F75"),3,FALSE),"") | F29: =IF(AND($A29<>"",$B29<>""),VLOOKUP($B29,INDIRECT($A29&"!A26:F75"),4,FALSE),"") | G29: =IF(AND($A29<>"",$B29<>""),VLOOKUP($B29,INDIRECT($A29&"!A26:F75"),6,FALSE),"")
... D49: =IF(AND($A49<>"",$B49<>""),VLOOKUP($B49,INDIRECT($A49&"!A26:F75"),2,FALSE),"") | E49: =IF(AND($A49<>"",$B49<>""),VLOOKUP($B49,INDIRECT($A49&"!A26:F75"),3,FALSE),"") | F49: =IF(AND($A49<>"",$B49<>""),VLOOKUP($B49,INDIRECT($A49&"!A26:F75"),4,FALSE),"") | G49: =IF(AND($A49<>"",$B49<>""),VLOOKUP($B49,INDIRECT($A49&"!A26:F75"),6,FALSE),"")
A50: 無盡破壞 | D50: 所持 道具
A51: 1-3
A52: 4-6
A53: 7-9
A54: 角色關係表 | H54: 角色設定
A55: 角色名 | C55: 感情 | E55: 羈絆値 | F55: 備註
E56: =IF($C56<>"",VLOOKUP($C56,INDIRECT($C$55&"!$A:$D"),2,FALSE),0) -> 0
E57: =IF($C57<>"",VLOOKUP($C57,INDIRECT($C$55&"!$A:$D"),2,FALSE),0) -> 0
E58: =IF($C58<>"",VLOOKUP($C58,INDIRECT($C$55&"!$A:$D"),2,FALSE),0) -> 0
E59: =IF($C59<>"",VLOOKUP($C59,INDIRECT($C$55&"!$A:$D"),2,FALSE),0) -> 0
...

Sheet 感情
A1: 感情 | B1: 羈絆值 | C1: 色調 | D1: 備註
A2: 基本感情 ▲ 創角時所獲得並使用的感情
A3: 嫉妬 | B3: 4 | C3: 瘋狂 | D3: 你強烈的意識到你比對方低等。
A4: 庇護 | B4: 2 | C4: 潔淨 | D4: 你認為保護這個人是你的使命。
A5: 喜愛 | B5: 2 | C5: 潔淨 | D5: 不知不覺間你注意到這個人，想看看他的反應。或許你會想欺負他看看吧？
A6: 無法置之不理 | B6: 2 | C6: 潔淨 | D6: 在你眼中他像個小孩一樣。
A7: 孽緣 | B7: 2 | C7: 潔淨 | D7: 因為長年的認識，你對對方的優點及缺點都十分清楚。
A8: 知恩圖報 | B8: 2 | C8: 潔淨 | D8: 因為他以前幫助過你，你充份感覺到他對你的恩義。
A9: 不安 | B9: 4 | C9: 瘋狂 | D9: 你懷疑對方對你的友情或者愛情。自己該不會被他討厭了吧？
A10: 反抗精神 | B10: 2 | C10: 潔淨 | D10: 抱持著競爭心或反抗心。你因為什麼對這個人抱著反抗的感情。
A11: 信賴 | B11: 2 | C11: 潔淨 | D11: 你覺得這個人真的十分值得信賴。
A12: 憧憬 | B12: 2 | C12: 潔淨 | D12: 這個人是你憧憬的人。你想要成為他那樣的人。
A13: 合得來 | B13: 2 | C13: 潔淨 | D13: 不知道為什麼你跟他很合得來。
A14: 逞強 | B14: 4 | C14: 瘋狂 | D14: 你希望在這人面前表現出毫無缺點。
... A23: 追憶故人 | B23: 4 | C23: 瘋狂 | D23: 你看到這個人會想起某個過去很重要的人。你會興起讓他成為「替代品」的想法。
A25: 追加感情 ▲ 情感對決及背反律所獲得並使用的感情
A26: 重要的朋友 | B26: 2 | C26: 潔淨 | D26: 因為過去發生了很多事情，造就你現在與對方如此親密的距離。
A27: 發誓 | B27: 2 | C27: 潔淨 | D27: 你向那個人發誓，會保護他不會再出現跟他一樣的犧牲者……等。
A28: 相思相愛 | B28: 8 | C28: 潔淨 | D28: 你跟對方是相思相愛的關係。
A29: 無法傳達的溫暖 | B29: 4 | C29: 瘋狂 | D29: 這份思念你確定無法傳達給那個人。你的心感到十分難過，因為你確定那個人已經「失去了」。
A30: 著急 | B30: 4 | C30: 瘋狂 | D30: 你什麼也不知道。為什麼沒注意到呢？你感到心急如焚。
A31: 敗北感 | B31: 4 | C31: 瘋狂 | D31: 又失敗了。這次也失敗了。為什麼？自己確實不是無力的，難道世界只有對自己不講理嗎？
A32: 破碎的信賴 | B32: 4 | C32: 瘋狂 | D32: 你覺得對方的言行已經是「背叛」了你，而陷入震驚狀態。明明是如此相信的！
A33: 無關心 | B33: 4 | C33: 瘋狂 | D33: 你絲毫不關心這個人。不管他生也好死也好、快樂也罷苦痛也罷，你絲毫不會動心。
A34: 愧疚 | B34: 4 | C34: 瘋狂 | D34: 你對對方做了不得了的事，抱著重大秘密的你覺得對他十分愧疚。
A35: 渴愛 | B35: 4 | C35: 瘋狂 | D35: 拜託你愛我，不要丟下我，不要放我一個留在這……。
A36: 獵物 | B36: 4 | C36: 瘋狂 | D36: 你對這個人抱著強烈得執著。認為他全部是自己的東西。
A37: 憎惡 | B37: 4 | C37: 瘋狂 | D37: 彷彿要將此身燃燒殆盡的憎悪。你絕對不會原諒對方。
... A49: 吸血衝動 | B49: 4 | C49: 瘋狂 | D49: 你非常想要這個人，這個人的靈魂、生命、全部的一切都想要。說到為什麼你會這麼想要呢？因為這是你最大的愛情表現。

Sheet 不完美的伊邪那歧
A1: 技能1 | B1: 技能2 | C1: 技能3 | D1: 技能4 | E1: 技能5 | F1: 技能6 | G1: 技能7 | H1: 技能8 | I1: 技能9 | J1: 技能10 | K1: 技能11 | L1: 技能12 | M1: 技能13 | N1: 技能14 | O1: 技能15 | P1: 技能16 | Q1: 技能17 | R1: 技能18 | S1: 技能19 | T1: 技能20 | U1: 技能21 | V1: 技能22 | W1: 技能23 | X1: 技能24 | Y1: 技能25 | Z1: 技能26 | AA1: 技能27 | AB1: 技能28
A2: {=INDIRECT('角色卡'!A17)} -> 狩人 | B2: {=INDIRECT('角色卡'!A18)} -> #REF! | C2: {=INDIRECT('角色卡'!A19)} -> #REF! | D2: {=INDIRECT('角色卡'!A20)} -> #REF! | E2: {=INDIRECT('角色卡'!A21)} -> #REF! | F2: {=INDIRECT('角色卡'!A22)} -> #REF! | G2: {=INDIRECT('角色卡'!A23)} -> #REF! | H2: {=INDIRECT('角色卡'!A24)} -> #REF! | I2: {=INDIRECT('角色卡'!A25)} -> #REF! | J2: {=INDIRECT('角色卡'!A26)} -> #REF! | K2: {=INDIRECT('角色卡'!A27)} -> #REF! | L2: {=INDIRECT('角色卡'!A28)} -> #REF! | M2: {=INDIRECT('角色卡'!A29)} -> #REF! | N2: {=INDIRECT('角色卡'!A30)} -> #REF! | O2: {=INDIRECT('角色卡'!A31)} -> #REF! | P2: {=INDIRECT('角色卡'!A32)} -> #REF! | Q2: {=INDIRECT('角色卡'!A33)} -> #REF! | R2: {=INDIRECT('角色卡'!A34)} -> #REF! | S2: {=INDIRECT('角色卡'!A35)} -> #REF! | T2: {=INDIRECT('角色卡'!A36)} -> #REF! | U2: {=INDIRECT('角色卡'!A37)} -> #REF! | V2: {=INDIRECT('角色卡'!A38)} -> #REF! | W2: {=INDIRECT('角色卡'!A39)} -> #REF! | X2: {=INDIRECT('角色卡'!A40)} -> #REF! | Y2: {=INDIRECT('角色卡'!A41)} -> #REF! | Z2: {=INDIRECT('角色卡'!A42)} -> #REF! | AA2: {=INDIRECT('角色卡'!A43)} -> #REF! | AB2: {=INDIRECT('角色卡'!A44)} -> #REF!
A3: 一般特技-弓系 ▲
A4: 弓掌握
A5: 相擊箭
A6: ★曲折箭
A7: ★多重箭
A8: ★強弓技巧
A9: ★速射技巧
A10: ★拋射技巧
A11: 製作：破魔箭
A12: 額外特技-弓系 ▲
A13: 落星
A14: 穿月
... A50: 長距離射擊

Sheet 風格
A1: 風格 | B1: 描述 | C1: 背反 | D1: 分類 | E1: 代償 | F1: 級別限制 | G1: 獲得感情 | H1: 代表角色 | I1: 效果 | J1: 風格覺醒條件 | K1: 追加效果
A2: 起源：進食 | B2: 你的靈魂內刻印著捕食其他生物的本能。 | C2: 「肉食獸的本能」 | D2: 通用 | E2: 恢復20點ＨＰ | F2: 無 | G2: 獵物 | H2: 白純里緒 | I2: 你的【近戰】＋６。使用後，你只能使用近戰特技。這個效果持續到戰鬥結束。 | J2: 發動背反律的狀態下，殺死設有獵物的對象 | K2: 基本能力的體力常時+10(非BONUS值)。 劇本開始時，丟1D6，劇本結束前，你必須設置對應數量的獵物感情給PC或是NPC，且殺死他們。 劇本中途風格覺醒時，將該需設置的人數-1。
A3: 起源：虛無 | B3: 你什麼都不關心，考試零分跟一百分對你來說沒有意義。 | C3: 「空虛之絆」 | D3: 常時 | E3: - | F3: 無 | G3: 無關心 | H3: 兩儀式 | I3: 你能加算情緒值的感情只有無關心。 但是這絆值＋１。 你的傷害常時－３，但是與攻擊對象的感情並非是無關心時，全判定＋１，傷害＋１。 | J3: 不限單一劇本，進行三次感情對決，轉換無關心 | K3: 你的背反律效果改為：你的判定與傷害常時+5。你無法對人設置無關心，也無法因為感情對決而設置無關心。
A4: 起源：禁忌 | B4: 你喜歡妹妹或是哥哥或是姐姐或是弟弟或是你爸你媽。 | C4: 「禁忌之愛」 | D4: 常時 | E4: - | F4: 無 | G4: 獨佔欲 | H4: 黑桐鮮花 | I4: 你在角色表設定一名血親角色，並且有「獨佔欲」。此絆值１０點，並且無法由感情對決消失。 如果你的血親跟你都處於戰鬥場景，你的全判定＋２。如果血親死亡，你的全判定－１０。 | J4: 對血親角色獨佔欲進行感情對決 | K4: 獨佔欲的絆值從10點上升到20點，並追加「獵物」，這兩個感情無法由感情對決消失。當你提出的要求被血親拒絕時，丟2D6，值在4以下時，你會承受不住壓力而殺死血親。
A5: 起源：靜止 | B5: 你有著停止事物的稀有才能，但是這力量也會影響到你自己的成長 | C5: 「靜止的世界」 | D5: 中斷 | E5: 劇本結束後得到經驗－２ | F5: 無 | G5: - | H5: 荒耶宗連 | I5: 你在對決判定時使用，對方達成值變成０。 | J5: 使用此背反律兩次 | K5: 除了概念武裝與上限傷害，你受到的實際傷害皆為0。你無法再獲得經驗點。
A6: 俯瞰風景 | B6: 你盼望著飛翔，但是這願望一旦成真時，你對於現實的認知又會如何呢。 | C6: 「俯瞰風景」 | D6: 常時／準備階段 | E6: - | F6: 無 | G6: 仰賴者（黑色） | H6: 秋堂秋緒 | I6: 你能夠改變自我認知，使自己產生在天空浮游的錯覺。戰鬥中使用【近戰】＋３，【射擊】－３，此效果持續到場景終了。 | J6: 無 | K6: 無
A7: 追星者 | B7: 直至今日，你依然在追逐觸動你心弦之夢。 | C7: 「所見即得」 | D7: 常時 | E7: - | F7: 無 | G7: 自我矛盾（黑色，對自己） | H7: 衛宮士郎 | I7: 你可以取得其他角色使用過的一個特技。此特技在劇本結束前可以使用，但是不能是額外特技。 | J7: 無 | K7: 無
A8: ＮＯＴ | B8: 你被霸凌，因而有天也有可能霸凌別人。 | C8: 「憎惡的肖像」 | D8: 中斷 | E8: 情緒點歸零 | F8: 無 | G8: 憎惡（黑色） | H8: 間桐櫻 | I8: 你行動不能時使用，你的生命，上限傷害，不良狀態全部回復。你在戰鬥結束前變成背反者，並且ＮＰＣ化。你對戰鬥場景內所有的角色登記負面感情（正面會進行感情對決變成負面）。 | J8: 無 | K8: 無
A9: 被創造者 | B9: 你的生命只是被賦予的機能──你不會為你為何而生，為何而死感到疑惑。 | C9: 「生命的意義」 | D9: 中斷 | E9: 情緒點歸零 | F9: 無 | G9: - | H9: 伊莉亞 | I9: 你可以無視代價發動一次無盡破壞，使用後你成為行動不能狀態。 | J9: 無 | K9: 無
A10: 潔癖症 | B10: 對你而言，與他人接觸，尤其是異性讓你極度不愉快。這是因為性格，或是什麼事件的創傷呢？ | C10: 「異性不信」 | D10: 常時 | E10: - | F10: 無 | G10: - | H10: 翡翠 | I10: 你對所有遇到的異性登記「隔意」，造成傷害時額外增加4點(獨立處理)。 | J10: 無 | K10: 無
A11: 盲信者 | B11: 你對某件事，或是人有著無庸置疑的忠誠心。無論對錯，你絕不會因此動搖。 | C11: 「愚忠」 | D11: 準備階段 | E11: - | F11: 無 | G11: 盲信(黑色) | H11: 第四次LANCER | I11: 你的ＨＰ恢復４０點。 | J11: 無 | K11: 無
A12: 天才 | B12: 你認為自己是天才，別人不過是你的踏腳石。 | C12: 「強者的驕傲」 | D12: 中斷 | E12: - | F12: 無 | G12: 優越感(黑色) | H12: 阿嚕巴 | I12: 你對決判定時使用，你得到會心。這效果發動後，你會對對決側的其他角色設定優越感。 | J12: 無 | K12: 無
... A34: 天選之人 | B34: 你的運氣總是比別人好，尤其在轉蛋遊戲上更能明顯展示差距。 | C34: 「命運女神的微笑」 | D34: 常時 | E34: - | F34: 無 | G34: - | H34: 無 | I34: 你的會心-1，會心上限+1(由3變成4)。一劇本一次，你可以在任何時候讓自己的判定大成功。此效果發動後會心上限成為0。同場景除了你之外還有其他同樣風格的角色存在時，你們的會心上限一同成為0。 | J34: 無 | K34: 無

Sheet 狩人
A1: 狩人
A2: 能力基本值
A3: 體力 | B3: 知覺 | C3: 理智 | D3: 意志
A4: 3 | B4: 3 | C4: 3 | D4: 3
A6: 級別修正表
A7: 等級 | B7: 1 | C7: 2 | D7: 3 | E7: 4 | F7: 5 | G7: 6 | H7: 7 | I7: 8 | J7: 9 | K7: 10
A8: 【近戰】 | B8: -2 | C8: -1 | D8: 0 | E8: 1 | F8: 2 | G8: 3 | H8: 4 | I8: 5 | J8: 6 | K8: 7
A9: 【射撃】 | B9: 2 | C9: 3 | D9: 4 | E9: 5 | F9: 6 | G9: 8 | H9: 10 | I9: 12 | J9: 14 | K9: 16
A10: 【精神】 | B10: -2 | C10: -1 | D10: 0 | E10: 0 | F10: 1 | G10: 2 | H10: 3 | I10: 4 | J10: 5 | K10: 6
A11: 【行動】 | B11: -2 | C11: -1 | D11: 0 | E11: 1 | F11: 3 | G11: 5 | H11: 7 | I11: 9 | J11: 11 | K11: 12
A12: 【生命力】 | B12: 0 | C12: 0 | D12: 5 | E12: 5 | F12: 8 | G12: 10 | H12: 12 | I12: 15 | J12: 18 | K12: 20
A13: 【集中力】 | B13: 0 | C13: 5 | D13: 5 | E13: 8 | F13: 8 | G13: 12 | H13: 15 | I13: 18 | J13: 18 | K13: 20
A14: 【防御點】 | B14: 0 | C14: 0 | D14: 0 | E14: 0 | F14: 0 | G14: 1 | H14: 1 | I14: 1 | J14: 1 | K14: 1
A16: 取得特技 ▲
A17: 初期取得：
A18: 掌握弓或是隱密通路，之後選擇一個自己喜歡的特技； 特殊：三級建立角色時初期級別是狩人等級三的話，人體理解或戰場掌握擇一+1級。
A20: 升級：
A21: 等級上升時，選擇一個喜歡的特技，等級五和十時再選一個； 狩人等級六和等級九時，可以選擇人體理解、戰場掌握擇一+1級，或是你的【體力】、【知覺】擇一紅利+1
A23: 技能名稱 | B23: 分類 | C23: 代價 | D23: 情緒獎勵 | E23: 取得限制 | F23: 效果
A24: 狩人
A25: 一般特技-弓系 ▲
A26: 弓掌握 | B26: 攻擊類型／射擊 | C26: 待機延遲2 | D26: 待機總合／2 | E26: 初期技能 | F26: 造成２Ｄ６+《體力》點傷害；每追加一回《４》點待機延遲，《》內的體力倍率+１且命中得到+１獎勵。
A27: 相擊箭 | B27: 攻擊類型／射擊 | C27: - | D27: 箭矢數*2 | E27: 無 | F27: 和〈弓掌握〉組合使用，這次攻擊不能組合其他進攻的特技，如果待機在0以上也不能進行攻擊。 操縱複數的箭矢的技巧，最初是同時射出2支箭矢。攻擊+2的[操縱箭矢數-1]次方點實際傷害，你也承受這傷害一半的上限傷害。 使用這特技時命中受到[操縱的箭矢數-1]的懲罰，並且主要階段結束後行動點數變成0、進入行動完成狀態。 ●你每擁有一個符合★條件的特技同時射出的箭矢數可以+1(沒有必須選擇最大數目的規則)，上限是9支。 ※數值x2的算法是2→4→8→16(以此類推)，最大256(實際傷害)/128(上限傷害)。
A28: ★曲折箭 | B28: 中斷 | C28: 代價傷害20- 狩人等級×2，行動點數10 | D28: 0 | E28: 無 | F28: 在弓傷害處理結束前變更攻擊對象，防禦側不能宣言防守特技。 一次戰鬥只能使用一次、對複數對象的攻擊無效。
A29: ★多重箭 | B29: 進攻／射擊 | C29: 代價傷害6× 對象數 | D29: 0 | E29: 無 | F29: 和弓組合使用，最多可以同時攻擊《體力》個對象；每額外攻擊一個對象你的命中受到-１懲罰。 不能和相擊箭組合使用。
A30: ★強弓技巧 | B30: 通常 | C30: 等同待機延遲的代價傷害 | D30: 0 | E30: 無 | F30: 弓每追加４點待機延遲，傷害就增加１Ｄ６。 使用技能後，你的行動順成為最後。 這期間進行反擊的話受到命中-４和傷害減半的懲罰。 一戰鬥最多使用２回、不能和其他技巧併用。
A31: ★速射技巧 | B31: 通常 | C31: 代價傷害６ | D31: ★特技數目點 | E31: 無 | F31: 〈弓掌握〉的待機延遲決定後《１+持有的★特技數目》點並命中+１。 被偷襲的回合你可以進行一回反擊。 一戰鬥最多使用兩次、不能和其他技巧併用。
A32: ★拋射技巧 | B32: 通常 | C32: - | D32: 2 | E32: 無 | F32: 和弓組合使用。 此次攻擊無法在命中階段被宣言《中斷》或《掩護》，但是只能攻擊敵方的［後排］。 一戰鬥最多使用2回、不能和其他技巧併用 戰鬥外進行隱密攻擊時，加入這個技巧能夠得到隱密+【持有的★特技數目x2】的效果（一場景1回）。
A33: 製作：破魔箭 | B33: 通常 | C33: 代價傷害15 | D33: 0 | E33: 超能力者、古神道、風水士級別 | F33: 製作一支破魔箭。效果參照道具頁。
A34: 額外特技-弓系 ▲
A35: 落星 | B35: 進攻／射擊 | C35: 代價傷害30 | D35: 0 | E35: 拋射技巧、強弓技巧、狩人等級6以上 | F35: 使〈拋射技巧〉和〈強弓技巧〉能夠組合使用。 拋射技巧的攻擊對象限制解除，並追加不能宣言《防守》特技； 強弓技巧敘述改成攻擊後，結束階段才進行命中處理。 該攻擊即使使用者行動不能仍需進行攻擊處理； 一戰鬥最多使用１回。 戰鬥外進行隱密攻擊時，和被動側的對抗自動勝出，但戰鬥外使用這特技的代價加倍（包含無盡破壞）。
A36: 穿月 | B36: 進攻／射擊 | C36: 弓待機+4的回數*15代價傷害 | D36: 0 | E36: 強弓技巧、速射技巧、狩人等級6以上 | F36: 使〈強弓技巧〉和〈速射技巧〉能夠組合使用。 強弓技巧的回合最後攻擊限制解除；速射技巧的命中+１改成，弓每+４待機延遲就額外+１命中。 一戰鬥最多使用１回。
A37: 神技 | B37: 常時 | C37: - | D37: 0 | E37: 狩人等級7以上 | F37: 〈相擊箭〉、〈落星〉、〈穿月〉任一追加下面的效果。 ●相擊箭：可能使用的箭矢數目+1；英靈設定無盡破壞時額外+1。 ●落星：可設成無盡破壞，無盡破壞時命中流程略過直接成功。 ●穿月：可設成無盡破壞，無盡破壞時忽略防禦側所持所有防禦效果。 ※三種效果不能共存或疊加。
A38: 一般特技-槍系 ▲
A39: 隱密通路 | B39: 常時 | C39: - | D39: 0 | E39: 初期技能 | F39: 劇本開始時持有手槍。一劇本最多得到【１】+［狩人等級／２］回支援。 新劇本開始時可以取得未持有的一種槍械，要再取得其他槍械時消耗1回支援。
A40: 進階槍種掌握 | B40: 常時 | C40: - | D40: 0 | E40: 無 | F40: 桿式步槍或突擊步槍擇一掌握；狩人等級6以上或以上兩者皆掌握時狙擊槍掌握可能。 這特技能夠重複取得。
A41: 槍械名人 | B41: 常時 | C41: - | D41: 0 | E41: 無 | F41: 隱密通路【】內的值+２、所有槍械情緒獎勵+２。 劇本開始時取得任意一種槍械或一單位的特殊子彈。 這特技不能取得魔術師聯動的特殊子彈。
A42: 彈藥支援 | B42: 常時／準備階段 | C42: - | D42: 0 | E42: 無 | F42: 你得到［狩人等級×１］點的EN和上限，可以用來取得槍械用的彈藥；消耗一回隱密通路支援可以補滿EN但不能超過上限。 準備階段使用，一回合內都有彈藥效果。戰鬥外使用，只有下一次攻擊有彈藥效果。 取得〈槍械名人〉後，你初期的EN和上限改成［狩人等級×２］計算。
A43: 戰術配件 | B43: 通常／準備階段 | C43: 隱密通路1回 | D43: 5 | E43: 隱密通路 | F43: 下列效果擇一持續到場景終了。 消音器：命中-３，狙擊或偷襲時隱密+【３】、獎勵依次遞減１。 消燄器：狙擊或偷襲時隱密+【２】、夜晚額外+【２】，獎勵依次遞減１。 雷射瞄準：射擊命中+【２】。 測距儀：射擊命中+【１】，命中判定達成值不會因其他因素減少。 戰術腳架：〈狙擊〉、〈長距離射擊〉命中+【２】、會心-【０】；次回合逃跑懲罰+５。 取得〈槍械名人〉後，本特技【】內的值+１。
A44: 戰術改造 | B44: 常時 | C44: 隱密通路1回 | D44: 15 | E44: 隱密通路、戰術配件 | F44: 永久強化持有的一種槍械，下列效果擇一，狙擊槍不可改造。 槍體改造：戰術配件可以擇二效果、強化彈使用可能。手槍需要付出兩次代價。 狙擊改裝：對不同區域命中+２、對同區域命中-２，〈狙擊〉使用可能化。 彈夾改造：一戰鬥只有1回，行動因狩人特技代價變成０時，行動增加２Ｄ６點。 輕化改裝：突擊步槍專用，口徑縮小、移除行動懲罰，雙持可能化。 在擁有的【１】個改造效果消失前你不能再使用此特技。 取得〈槍械名人〉後，本特技【】內的值+１、追加火控元件改造選擇。 火控元件：將行動點數-10時，攻擊可以進行2回，行動懲罰+１２；桿式步槍不可改造。
...

Sheet 劍士
A1: 劍士
A2: 能力基本值
A3: 體力 | B3: 知覺 | C3: 理智 | D3: 意志
A4: 4 | B4: 4 | C4: 2 | D4: 2
A6: 級別修正表
A7: 等級 | B7: 1 | C7: 2 | D7: 3 | E7: 4 | F7: 5 | G7: 6 | H7: 7 | I7: 8 | J7: 9 | K7: 10
A8: 【近戰】 | B8: 0 | C8: 1 | D8: 2 | E8: 3 | F8: 6 | G8: 8 | H8: 10 | I8: 12 | J8: 14 | K8: 16
A9: 【射撃】 | B9: -2 | C9: -1 | D9: 0 | E9: 1 | F9: 2 | G9: 3 | H9: 4 | I9: 5 | J9: 6 | K9: 7
A10: 【精神】 | B10: -2 | C10: -1 | D10: 0 | E10: 1 | F10: 2 | G10: 3 | H10: 4 | I10: 5 | J10: 6 | K10: 7
A11: 【行動】 | B11: -1 | C11: 0 | D11: 1 | E11: 2 | F11: 5 | G11: 7 | H11: 9 | I11: 11 | J11: 13 | K11: 15
A12: 【生命力】 | B12: 0 | C12: 4 | D12: 13 | E12: 19 | F12: 22 | G12: 25 | H12: 28 | I12: 31 | J12: 34 | K12: 37
A13: 【集中力】 | B13: 0 | C13: 8 | D13: 8 | E13: 11 | F13: 12 | G13: 14 | H13: 15 | I13: 18 | J13: 18 | K13: 21
A14: 【防御點】 | B14: 0 | C14: 0 | D14: 0 | E14: 1 | F14: 1 | G14: 2 | H14: 2 | I14: 2 | J14: 3 | K14: 3
A16: 取得特技 ▲
A17: 初期取得：
A18: 得到「段位」、「流派」。
A20: 升級：
A21: 等級上升之時、選取一個喜歡的特技。每逢５等、１０等時，可以額外再取得一個特技。
A23: 技能名稱 | B23: 分類 | C23: 代價 | D23: 情緒獎勵 | E23: 取得限制 | F23: 效果
A24: 劍士
A25: 一般特技 ▲
A26: 段位 | B26: 常時 | C26: - | D26: 0 | E26: 無 | F26: 你身為劍士的段位資格，會隨著同一流派相關技能數而改變。 一到二：切紙 三到四：目錄 五到六：印可 七到八：大目錄 九以上：免許皆傳。 此技能本身不算在相關技能數。
A27: 流派 | B27: 常時 | C27: - | D27: 2 | E27: 無 | F27: 從以下流派中擇一入門，此特技可重複取得。此技能計算在相關技能數。 二天一流： 你獲得技能■二天一流。 一刀流： 你獲得技能■一刀流。 秀綱流居合術： 你獲得技能■秀綱流。
A28: 二天一流 | B28: 攻擊類型／近戰 | C28: - | D28: 2 | E28: 無 | F28: 使用大小太刀的攻擊。指定一對象造成２Ｄ６傷害，並可宣言任一架式。〈上段〉本次傷害追加１Ｄ６。〈下段〉本次命中達成值追加２。
A29: 一刀流 | B29: 攻擊類型／近戰 | C29: - | D29: 2 | E29: 無 | F29: 使用中、或是小太刀進行攻擊。指定一對象造成２Ｄ６＋４傷害，並可宣言任一架式。〈背車刀〉本次命中追加１。〈切落〉你切換到待機狀態，並且可反擊任何攻擊，若是反擊時的命中值高於對手命中，跳過雙方傷害階段直接結束，此架式進行完後你不會進入已行動狀態。
A30: 秀綱流 | B30: 攻擊類型／近戰 | C30: - | D30: 2 | E30: 無 | F30: 使用居合刀進行的攻擊。指定一對象造成１Ｄ６傷害。並可宣言任一架式。〈跪座〉待機延遲４，本次攻擊傷害追加２Ｄ６，你與對方皆無法宣言反擊。〈站姿〉本次命中值追加３。
A31: 圓極 | B31: 準備階段 | C31: 代價傷害5 | D31: 0 | E31: 段位‧切紙、流派──二天一流。 | F31: 二刀流的起手架式。回合終了為止你的命中達成值＋２，防禦值＋２。
A32: 左右反打 | B32: 防禦 | C32: - | D32: 2 | E32: 段位‧切紙、流派──二天一流 | F32: 你可針對朝你發出的攻擊進行以下宣言：〈左反打〉對手此次攻擊的傷害與命中＋２，在你被攻擊或是迴避之後，你可以無視行動狀態，以對手為對象進行攻擊，此次攻擊命中＋４。〈右反打〉對手此次攻擊的傷害與命中＋４，在你被攻擊或是迴避之後，你可以無視行動狀態，以對手為對象進行攻擊，此次攻擊傷害＋２Ｄ６。
A33: 陰陽雙舞 | B33: 進攻／近戰 | C33: - | D33: 2 | E33: 段位‧目錄、流派──二天一流 | F33: 二天一流的招式變化，你可以進行以下宣言：〈陽舞〉以大太刀為主，本次傷害追加１Ｄ６。〈陰舞〉以小太刀為主，本次命中達成值＋３。
A34: 紅葉疊舞 | B34: 通用 | C34: 代價傷害3 | D34: 2 | E34: 段位‧目錄、流派──二天一流 | F34: 對手迴避攻擊之後，你可以命中達成值－６再次進行攻擊。此技能一回合只能使用一次。
A35: 組太刀 | B35: 準備階段 | C35: 代價傷害5 | D35: 2 | E35: 段位‧印可、流派──二天一流 | F35: 二天一流的起手架式變化。回合終了為止你可以對朝你而來攻擊進行兩次迴避。
A36: 二刀八相 | B36: 常時 | C36: - | D36: 0 | E36: 段位‧印可、流派──二天一流 | F36: 宮本武藏創造的架式。你的二天一流敘述文追加「本次攻擊你額外進行兩回命中擲骰，每成功一次傷害追加１Ｄ６」。
A37: 轉變落打 | B37: 防禦 | C37: 代價傷害15 | D37: 2 | E37: 段位‧大目錄、流派──二天一流 | F37: 當你受到來自同區域的傷害後，你可以無視行動狀態，以對手為對象進行攻擊，第一次承受這技能造成反擊的對手無法迴避，第二次以後須受到迴避達成值－４的懲罰。
... A54: 秀綱流居合六本目「銜草」 | B54: 防禦 | C54: - | D54: 2 | E54: 段位‧大目錄、流派──秀綱流 | F54: 以真刀刀柄強行阻擋對方的攻擊。抵銷一次空手以外的近戰攻擊，使用後武器損毀。
A55: 額外特技 ▲
A56: 五輪太刀 | B56: 常時 | C56: - | D56: 0 | E56: 段位‧免許皆傳、流派──二天一流 | F56: 你手上有大小太刀時，傷害增加２Ｄ６，攻擊範圍可包含相鄰區域。並得到以下架式： 〈地太刀〉你可以付出２０點行動點使本次攻擊的命中值＋〔你的劍士等級〕。 〈火太刀〉你可以付出２０點行動點使本次攻擊的實際傷害成為兩倍。 〈風太刀〉你可以付出２０點行動點使本次攻擊射程成為全區域。 〈水太刀〉你可以付出２０點行動點進行兩次攻擊。 〈空太刀〉你可以付出２０點行動點，反擊即使不以你為對象的技能。此次行動完你不會進入已行動狀態。
A57: 奧義‧一吋劍理 | B57: 通用 | C57: 代價傷害30 | D57: 2 | E57: 段位‧免許皆傳、流派──二天一流 | F57: 指定一名對手，從該對手而來的攻擊到戰鬥結束前你獲得【你劍士等級】的防禦值修正，這效果無法對同樣的對手疊加。可以對不同角色複數使用。
A58: 金翅烏王劍 | B58: 進攻／近戰 | C58: 代價傷害25 | D58: 2 | E58: 段位‧免許皆傳、流派──一刀流、葉切 | F58: 以飛鳥為底，發展到最終形式的一刀流劍技，此次傷害追加《３》Ｄ６＋《３》，命中達成值＋《３》。另外，攻擊後你可以無視阻礙移動。
A59: 奧義‧夢想劍 | B59: 通用 | C59: 代價傷害50 | D59: 2 | E59: 段位‧免許皆傳、流派──一刀流 | F59: 你的傷害追加《你的劍士等級》Ｄ６，攻擊射程成為全區域。獲得此技能後不需支付代價也有常時效果──你不會被〔你的劍士等級〕以下的角色奇襲成功，即便你在睡覺中遇襲，身體也能自動擺出架式應戰。你在準備階段能夠使用所有的一刀流起手架式效果。
A60: 秀綱流居合七本目「氣圓」 | B60: 常時 | C60: - | D60: 0 | E60: 段位‧免許皆傳、流派──秀綱流 | F60: 當你行動點在２０以上的時候，技能〈秀綱流居合一本目「始」〉攻擊射程成為全區域。
...

Sheet 狩獵者
A1: 狩獵者
A2: 能力基本值
A3: 體力 | B3: 知覺 | C3: 理智 | D3: 意志
A4: 4 | B4: 4 | C4: 4 | D4: 4
A6: 級別修正表
A7: 等級 | B7: 1 | C7: 2 | D7: 3 | E7: 4 | F7: 5 | G7: 6 | H7: 7 | I7: 8 | J7: 9 | K7: 10
A8: 【近戰】 | B8: 0 | C8: 1 | D8: 2 | E8: 3 | F8: 7 | G8: 9 | H8: 11 | I8: 13 | J8: 15 | K8: 17
A9: 【射撃】 | B9: 0 | C9: 1 | D9: 2 | E9: 3 | F9: 7 | G9: 9 | H9: 11 | I9: 13 | J9: 15 | K9: 17
A10: 【精神】 | B10: -4 | C10: -3 | D10: -2 | E10: -1 | F10: 0 | G10: 1 | H10: 1 | I10: 1 | J10: 1 | K10: 1
A11: 【行動】 | B11: 1 | C11: 2 | D11: 3 | E11: 4 | F11: 8 | G11: 10 | H11: 12 | I11: 14 | J11: 16 | K11: 18
A12: 【生命力】 | B12: 0 | C12: 8 | D12: 14 | E12: 20 | F12: 32 | G12: 38 | H12: 44 | I12: 50 | J12: 56 | K12: 62
A13: 【集中力】 | B13: 0 | C13: 0 | D13: 0 | E13: 0 | F13: 0 | G13: 0 | H13: 0 | I13: 0 | J13: 0 | K13: 0
A14: 【防御點】 | B14: 0 | C14: 1 | D14: 1 | E14: 1 | F14: 2 | G14: 2 | H14: 2 | I14: 2 | J14: 2 | K14: 3
A16: 取得特技 ▲
A17: 初期取得：
A18: 得到「人外血脈」，然後再選擇一個自己喜歡的特技。
A20: 升級：
A21: 等級上升之時、選取一個喜歡的特技。每逢５等、１０等時，可以額外再取得一個特技。
A23: 技能名稱 | B23: 分類 | C23: 代價 | D23: 情緒獎勵 | E23: 取得限制 | F23: 效果
A24: 狩獵者
A25: 一般特技 ▲
A26: 人外血脈──死徒 | B26: 常時 | C26: - | D26: 0 | E26: - | F26: 你獲得以下常時 ► 最大生命常時增加２０，概念武裝與上限傷害以外的攻擊造成實際傷害減輕五分之一。 ► 你無法從自己的技能 (包含效果)或是感情獲得，必須透過吸食人血獲得。每徹底吸食（殺死）一個人，ＨＰ與ＴＰ恢復１０Ｄ６，劇本進行中每天至少需吸食［你的狩獵者等級］次人血（不殺人可，但是不會獲得ＨＰ或ＴＰ補充）。 ► 每減少一次，當日結束前獲得［減少次數］Ｄ６的ＨＰ與ＴＰ傷害。 你的戰鬥能力會受到ＴＰ現存值影響： ► ０：你失去一切近戰射擊精神行動的級別加成，受到－５的行為判定修正，傷害減少２Ｄ６，失去實際傷害減免效果。 ► １～３０：戰鬥中你受到－３的行為判定修正，傷害減少１Ｄ６，失去實際傷害減免效果。 ► ３１～５０：無。 ► ５１～７０：戰鬥中你得到＋３的行為判定修正。 ► ７１～９９：戰鬥中你得到＋３的行為判定修正，防禦值上升３，傷害追加２Ｄ６。 ► １００以上：戰鬥中你得到＋５的行為判定修正，防禦值上升５，傷害追加３Ｄ６。
A27: 人外血脈──鬼種 | B27: 常時 | C27: - | D27: 0 | E27: - | F27: 你獲得以下常時 ► 劇本開始時集中力增加［你的狩獵者級別Ｘ１０］，每使用一次鬼種技能時，需接受難易度［你的狩獵者級別Ｘ３］的反轉衝動判定，此判定可選擇精神或是體力判定，或是支付同等代價傷害代替判定。 ► 放棄判定，或是失敗的場合，你進入反轉衝動狀態。 反轉衝動： ► 你所有狩獵者技能（包含空手）的傷害增加８點，你失去防禦點。 ► 戰鬥中你受到＋３的行為判定修正，每回合結束時恢復［你的狩獵者級別Ｘ５］的ＴＰ。 ► 你會不顧一切與場景內所有角色戰鬥，直至你成為行動不能狀態，或是對方全部死亡。 ► 每回合結束時可以接受難易度［你的狩獵者級別Ｘ３（最低為９）］的解除反轉衝動判定，此次判定不能以支付代價傷害代替。
A28: 人外血脈──被造物 | B28: 常時 | C28: - | D28: 0 | E28: - | F28: 効果： 取得此技能後，無法取得其他〈人外血脈〉技能： 你獲得以下常時狀態： ► 從【近戰】跟【射擊】選擇一項增加（你的狩獵者級別），另一項減少（你的狩獵者級別）。 ► 從【生命力】跟【集中力】選擇一項增加（你的狩獵者級別*5），另一項減少（你的狩獵者級別*5）。
A29: 殺戮之手 | B29: 攻擊類型／近戰 | C29: - | D29: 0 | E29: 死徒 | F29: 指定對象一人，給予３Ｄ６傷害。
A30: 獸爪 | B30: 攻擊類型／近戰 | C30: - | D30: 0 | E30: 死徒 | F30: 指定對象一人，給予２Ｄ６＋【體力】傷害。
A31: 獵犬之牙 | B31: 進攻／近戰 | C31: - | D31: 0 | E31: 死徒 | F31: 實傷後效果，你可以指定另一名對象再次攻擊，這個特技一回合只能使用一次。此特技發動的攻擊無法選擇一名以上的對象。第二個攻擊目標可以選擇相鄰區域的對象。
A32: 力量破壞 | B32: 進攻類型／近戰 | C32: 代價傷害5 | D32: 0 | E32: 死徒 | F32: 你減少Ｎ點命中，傷害增加《Ｎ－１》Ｄ６。
A33: 蓄氣 | B33: 進攻類型／近戰 | C33: 代價傷害5 | D33: 0 | E33: 死徒 | F33: 你的傷害增加＋《你的防禦點》
A34: 生命吸收 | B34: 常時 | C34: - | D34: 0 | E34: 死徒 | F34: 你給予其他角色實傷時，恢復該傷害三分之一的ＨＰ。
A35: 鋼鐵之膚 | B35: 常時 | C35: - | D35: 0 | E35: 死徒 | F35: 防禦點＋２
A36: 自我再生 | B36: 常時 | C36: - | D36: 0 | E36: 死徒 | F36: 以你為對象，每到結束階段恢復現存ＴＰ五分之一的ＨＰ。
A37: 赤朱覺醒 | B37: 準備階段 | C37: 代價傷害6 | D37: 0 | E37: 鬼種 | F37: 回合終了前你進入奮起狀態。你所有屬性值＋《２》。
... A44: 毒噬 | B44: 通用 | C44: 代價傷害10 | D44: 0 | E44: 鬼種 | F44: 你的攻擊產生實傷後附帶毒效果。
A45: 額外特技 ▲
A46: 鬼人肉體 | B46: 常時 | C46: - | D46: 0 | E46: 狩獵者等級３以上 | F46: 你受到的實際傷害在你的【體力】以下時變成０。但是對上限傷害無法發揮效果。
A47: 死種創造 | B47: 常時 | C47: - | D47: 0 | E47: 狩獵者等級３以上、死徒 | F47: 被你吸血而死的生命，會成為死者（詳見移動屍體）。被他們所殺死的人，視為你殺死可吸食，然而你無法讓死者產生死者。
A48: 獸化 | B48: 準備階段 | C48: 代價傷害10 | D48: 0 | E48: 狩獵者等級 ４以上、死徒 | F48: 回合終了前你的近戰＋４，防禦＋４。
A49: 橫掃之風 | B49: 通用 | C49: 代價傷害15 | D49: 0 | E49: 狩獵者等級５以上、死徒 | F49: 你的攻擊以同區域敵方全體為對象。
A50: 番外序列 | B50: 常時 | C50: - | D50: 0 | E50: 狩獵者等級８以上、死徒、死種創造 | F50: 實力已逼近２７祖的死徒獲得的稱號。你的基本四屬能力＋［你的狩獵者等級－７］，防禦值＋［你的狩獵者等級－７］，最大生命常時增加２０，ＴＰ上限成為１５０。
...

Sheet 代行者
A1: (級別)
A2: 能力基本值
A3: 體力 | B3: 知覺 | C3: 理智 | D3: 意志
A4: 3 | B4: 3 | C4: 3 | D4: 3
A6: 級別修正表
A7: 等級 | B7: 1 | C7: 2 | D7: 3 | E7: 4 | F7: 5 | G7: 6 | H7: 7 | I7: 8 | J7: 9 | K7: 10
A8: 【近戰】 | B8: 1 | C8: 2 | D8: 3 | E8: 4 | F8: 5 | G8: 6 | H8: 7 | I8: 8 | J8: 9 | K8: 10
A9: 【射撃】 | B9: 1 | C9: 2 | D9: 3 | E9: 4 | F9: 5 | G9: 6 | H9: 7 | I9: 8 | J9: 9 | K9: 10
A10: 【精神】 | B10: 1 | C10: 2 | D10: 3 | E10: 4 | F10: 5 | G10: 6 | H10: 8 | I10: 10 | J10: 12 | K10: 14
A11: 【行動】 | B11: 1 | C11: 2 | D11: 3 | E11: 4 | F11: 5 | G11: 6 | H11: 8 | I11: 10 | J11: 12 | K11: 14
A12: 【生命力】 | B12: 2 | C12: 4 | D12: 6 | E12: 8 | F12: 10 | G12: 12 | H12: 14 | I12: 16 | J12: 18 | K12: 20
A13: 【集中力】 | B13: 2 | C13: 4 | D13: 6 | E13: 8 | F13: 10 | G13: 11 | H13: 12 | I13: 13 | J13: 14 | K13: 15
A14: 【防御點】 | B14: 0 | C14: 0 | D14: 0 | E14: 0 | F14: 1 | G14: 1 | H14: 1 | I14: 1 | J14: 1 | K14: 1
A16: 取得特技 ▲
A17: 初期取得：
A18: 選擇兩個自己喜歡的特技。
A20: 升級：
A21: 等級上升之時、選取一個喜歡的特技。每逢５等、１０等時，可以額外再取得一個特技。
A23: 技能名稱 | B23: 分類 | C23: 代價 | D23: 情緒獎勵 | E23: 取得限制 | F23: 效果
A24: 代行者
A25: 一般特技 ▲
A26: 黑鍵持有 | B26: 常時 | C26: - | D26: 0 | E26: 無 | F26: 劇本開始時，你得到［你的代行者等級Ｘ２］數量黑鍵。黑鍵具有１Ｄ６＋４傷害。並為概念武裝。但是無論拿來揮砍或是投擲，皆會因本體精煉度低而損毀。受到黑鍵傷害的對象，獲得不良狀態【復原詛咒無效化】。 【復原詛咒無效化】：你無法因為自己的技能 獲得ＨＰ回復，此效果持續到下個回合終了。
A27: 異端審判人 | B27: 常時 | C27: - | D27: 0 | E27: 無 | F27: 通過聖堂教會層層磨練，以將體術昇華至頂點。你的近戰與射擊常時＋１。生命力提升［你的代行者等級Ｘ２］，集中力提升［你的代行者等級Ｘ２］。防禦點＋１。
A28: 秘跡封印 | B28: 通常 | C28: 代價傷害2 | D28: 2 | E28: 無 | F28: 對象身上所持：秘跡獲得不良狀態【封印】。 發動此特技必須接觸到目標物品，或是與持有者進行近戰命中對抗。 【封印】：秘跡失去其效果，此效果持續到下個回合／場景結束終了。
A29: 聖痕持有 | B29: 常時 | C29: - | D29: 0 | E29: 無 | F29: 你獲得以下常時： 從【生命力】跟【集中力】選擇一項減少（你的代行者級別），從【近戰】跟【射擊】選擇一項增加（你的代行者級別）。
A30: 異端消抹偏執：竭誠信仰 | B30: 常時 | C30: - | D30: 0 | E30: 無 | F30: 取得此特技後，不得取得其他〈異端消抹偏執〉特技。 對非人、魔術師傷害追加2D6點；其他傷害減1D6點。
A31: 異端消抹偏執：不信者 | B31: 常時 | C31: - | D31: 0 | E31: 無 | F31: 取得此特技後，不得取得其他〈異端消抹偏執〉特技。 傷害常時增加1D6點。
A32: 所持：秘跡 | B32: 常時 | C32: - | D32: 0 | E32: 無 | F32: 你可以持有一秘跡，此特技可重複取得。
A33: 影縫 | B33: 進攻／共通 | C33: - | D33: 0 | E33: 無 | F33: 實傷後效果，對象獲得不良狀態麻痺。
A34: 強化式典 | B34: 進攻／共通 | C34: 待機延遲2 | D34: 2 | E34: 無 | F34: 你的傷害追加《１Ｄ６＋１》點。宣言反擊時此特技失去效果。
A35: 多重投擲 | B35: 進攻類型／射擊 | C35: 待機延遲3 | D35: 0 | E35: 無 | F35: 你可以一次使用【你的代行者等級】黑鍵進行攻擊，此數值不得大於６。攻擊對象可為不同人。宣言反擊時此特技失去效果。
A36: 固定式典 | B36: 準備階段 | C36: 一把黑鍵代價傷害2 | D36: 0 | E36: 無 | F36: 使你的黑鍵損毀率變為二分之一。這回合使用黑鍵時，命中+《1》，傷害+3。
A37: 黑鍵製作 | B37: 通常 | C37: - | D37: 0 | E37: 無 | F37: 戰鬥外時可使用，每一天可得到［你的代行者等級／２］數量的黑鍵，四捨五入去小數點。
... A43: 神威之鎖 | B43: 準備階段 | C43: 代價傷害15 | D43: 0 | E43: 無 | F43: 指定一對象，與其進行【精神】對決。對象失敗的話，此回合行動力－《１０》，非人者的話－《１５》。
A44: 額外特技 ▲
A45: 式典魔術 | B45: 準備階段 | C45: 一把黑鍵代價傷害7 | D45: 0 | E45: 代行者等級5以上、火葬式典、土葬式典、風葬式典 | F45: 你可以同時賦予黑鍵火葬、土葬、風葬的效果。
A46: 強制洗禮 | B46: 進攻／共通 | C46: 代價傷害10 | D46: 0 | E46: 代行者等級5以上、神威之鎖、異端審判人 | F46: 實傷後效果，對象獲得不良狀態【洗禮】。如果為非人者，追加受到２Ｄ６傷害。
A47: 埋葬機關候補 | B47: 常時 | C47: - | D47: 0 | E47: 代行者等級5以上、所持：秘跡、異端審判人 | F47: 你的近戰與射擊常時+２，生命力提升【你的代行者等級Ｘ２】，集中力提升【你的代行者等級Ｘ２】。
A48: 所持：聖典 | B48: 常時 | C48: - | D48: 0 | E48: 代行者等級5以上、異端審判人 | F48: 你可從下列擇一【聖典】持有： ■聖葬砲典 分類：攻撃類型／射撃 代償：待機延遲10 効果：當你具有「聖典制御刻印」時可使用。 指定對象1人，給予【你的代行者等級】D6的傷害，本次傷害為概念武裝。 宣言反擊時，傷害須扣減未待機完畢之行動點。 ■第七聖典 分類：攻撃類型／共通 代償：待價傷害12 効果：當你具有「聖典制御刻印」時可使用。 指定對象1人，給予4D6+【你的代行者等級】的傷害，本次傷害為概念武裝。 ■春綻聖典 分類：通常 代償：－ 効果：當你具有「聖典制御刻印」時可使用。 劇本開始時自動補充【你的代行者等級*2】頁數。 攻擊時每使用一頁，提升你的命中1點或是傷害1點。 ■正式外典迦瑪列 分類：通常 代償：代價傷害20 効果：當你具有「聖典制御刻印」時可使用。 指定對象一人，此次攻擊的實際傷害為兩倍。 對象若為吸血種，實際傷害為三倍。
A49: 鐵甲作用 | B49: 進攻／共通 | C49: 待機延遲10 | D49: 0 | E49: 埋葬機關候補 | F49: 此技能可與式典技能併用。你的傷害追加【你的代行者等級】點。
...

Sheet 超能力者
A1: 超能力者
A2: 能力基本值
A3: 體力 | B3: 知覺 | C3: 理智 | D3: 意志
A4: 2 | B4: 2 | C4: 2 | D4: 2
A6: 級別修正表
A7: 等級 | B7: 1 | C7: 2 | D7: 3 | E7: 4 | F7: 5 | G7: 6 | H7: 7 | I7: 8 | J7: 9 | K7: 10
A8: 【近戰】 | B8: 0 | C8: 0 | D8: 0 | E8: 0 | F8: 0 | G8: 0 | H8: 0 | I8: 0 | J8: 0 | K8: 1
A9: 【射撃】 | B9: 0 | C9: 0 | D9: 0 | E9: 0 | F9: 0 | G9: 0 | H9: 0 | I9: 0 | J9: 0 | K9: 1
A10: 【精神】 | B10: 1 | C10: 2 | D10: 3 | E10: 4 | F10: 6 | G10: 8 | H10: 10 | I10: 12 | J10: 14 | K10: 16
A11: 【行動】 | B11: 0 | C11: 0 | D11: 0 | E11: 0 | F11: 0 | G11: 0 | H11: 0 | I11: 0 | J11: 0 | K11: 1
A12: 【生命力】 | B12: 0 | C12: 0 | D12: 0 | E12: 0 | F12: 1 | G12: 2 | H12: 3 | I12: 4 | J12: 5 | K12: 6
A13: 【集中力】 | B13: 0 | C13: 0 | D13: 0 | E13: 0 | F13: 0 | G13: 0 | H13: 0 | I13: 0 | J13: 0 | K13: 1
A14: 【防御點】 | B14: 0 | C14: 0 | D14: 0 | E14: 0 | F14: 0 | G14: 0 | H14: 0 | I14: 0 | J14: 0 | K14: 1
A16: 取得特技 ▲
A17: 初期取得：
A18: 從「一代變異」「血脈」中選一，而後再選擇一個自己喜歡的特技。
A20: 升級：
A21: 等級上升之時、選取一個喜歡的特技。每逢５等、１０等時，可以額外再取得一個特技。
A23: 技能名稱 | B23: 分類 | C23: 代價 | D23: 情緒獎勵 | E23: 取得限制 | F23: 效果
A24: 超能力者
A25: 一般特技 ▲
A26: 一代變異 | B26: 常時 | C26: - | D26: 0 | E26: 未持有「血脈」 | F26: 你天生就開啟著與眾不同的「頻道」。 所有判定常時+《1》。若你只擁有超能力者級別，《》的值更改為1D6。
A27: 血脈 | B27: 常時 | C27: - | D27: 0 | E27: 未持有「一代變異」 | F27: 你繼承著好幾代累積而來的「異能」。 你的近戰、射擊、行動、生命力、集中力修正值增加﹝【精神】/3﹞(去小數點)。
A28: 過去視 | B28: 通用 | C28: - | D28: 0 | E28: 無 | F28: 你可窺視他人的記憶，化為自己的虛擬體驗。需要判定的場合使用精神。這個技能一天可以使用【你的超能力等級】次數。將這個技能以無盡破壞使用的話，可以在你的【超能力等級】／３回合內，拷貝使用對象所有戰鬥技術技能。
A29: 未來視──預測 | B29: 常時／通用 | C29: - | D29: 0 | E29: 無 | F29: 你常時理智的判定＋２。戰鬥中從第二回合開始，每回合你的命中與迴避判定達成值＋１。將這個技能以無盡破壞使用的話，可以在你的【超能力等級】／３回合內，命中與迴避判定達成值額外增加【超能力等級】。
A30: 未來視──測定 | B30: 常時／通用 | C30: - | D30: 0 | E30: 無 | F30: 你常時意志的判定＋２。你可以在任何判定的時候使用這個技能產生會心，這個會心一劇本只能使用一次。將這個技能以無盡破壞使用的話，可以再次會心，這個無盡破壞產生的會心沒有劇本使用限制。
A31: 現在視 | B31: 常時／通用 | C31: - | D31: 0 | E31: 無 | F31: 你偶爾可以同時使用兩種以上的感覺來認識事物。能分辨文字裡包含的顏色、能聽見聲音的形狀、能感受語言的美味和苦味。此狀態面對問題時，不需特別思考也能直覺似地通曉答案。你的１、１視同６、６，將這技能以無盡破壞使用的話，可以在你的【超能力等級】／３回合內，你在４以下以及１０以上的骰數都視為會心。
A32: 感應 | B32: 通用 | C32: - | D32: 0 | E32: 無 | F32: 你每扣掉Ｎ點體力或是情緒值，就可以將同等戰鬥數值數值強化到他人身上。此數值不得超過你的【超能力者】級別。
A33: 念寫 | B33: 常時 | C33: - | D33: 0 | E33: 無 | F33: 將心中所想的事物顯現在紙張或其他媒介上的能力。 進行交流獲取情報的判定常時+2。 你可以把心中的想法化為不超過20字的文字傳送給肉眼所見的某人，需要判定的場合使用精神。 這個技能一天可以使用【超能力者等級】次。 將這個技能以無盡破壞使用的話，使一名對象命中和迴避下降【超能力者等級】直到戰鬥結束。
A34: 念附 | B34: 準備階段 | C34: 代價傷害15點 | D34: 0 | E34: 無 | F34: 一戰鬥一次。在一回合內可以使用精神代替行動、近戰、射擊判定。
A35: 透視 | B35: 常時／通用 | C35: - | D35: 0 | E35: 無 | F35: 你的知覺判定常時+2。 即使人不在現場，你可以在一瞬間看見某個你去過地點的景象。 這個技能一天可以使用【超能力者等級】次。 將這個技能以無盡破壞使用的話，可以對你使用透視看到的目標進行一次攻擊。
A36: 能力封印 | B36: 常時 | C36: - | D36: 0 | E36: 無 | F36: 選取一個你擁有的特技，將其內文數值+3，一個劇本只能使用三次。特技有疑慮問題由GM判定。「嗚啊啊──我的右手......！！」
A37: 概念破壞 | B37: 攻擊類型／精神 | C37: - | D37: 0 | E37: 一代變異 | F37: 指定全區域一對象造成《3D6》傷害。
... A40: 淨眼 | B40: 常時／準備階段 | C40: 代價傷害5點 | D40: 0 | E40: 血脈 | F40: 當你遇到其他角色時，你能得知該角色擁有的級別。 戰鬥中使用時，隨機得知對象的一項戰鬥數值。 需要判定的場合使用精神。
A41: 額外特技 ▲
A42: 退魔衝動 | B42: 常時 | C42: - | D42: 0 | E42: 血脈 | F42: 你的近戰、射擊、行動、生命力、集中力級別修正值成為［【精神】／2］(去小數點)。 你面對混有【狩獵者】職級的PC、NPC戰鬥時，全判定+5。你能察覺有【狩獵者】職級者，初次接觸時立即進行【難易度１０+對方狩獵者等級】的精神判定骰 ，失敗或放棄的話你會失去理智，不顧一切殺死對方。此效果維持到你行動不能或是對方死亡。 二次見面以後不需判定。
A43: 阿賴耶識的抑止力 | B43: 常時 | C43: - | D43: 0 | E43: 超能力者等級四以上 | F43: 一劇本１０人以上角色死亡時發動。 你到劇本結束為止，每到場景終了（戰鬥中是到回合終了為止）增加100點情緒值。 你的全判定＋1D6(這個數值不能超過你的超能力者等級)，無盡破壞使用次數+1，已使用次數重置。
A44: 極限 | B44: 常時 | C44: - | D44: 0 | E44: 超能力者等級四以上 | F44: 一劇本一次，你進入行動不能時自動發動，你回覆［正面感情情緒值總和］ＨＰ，並且此效果在［你的超能力等級／３］回合內不限次數發動。
A45: 生命的光輝 | B45: 常時 | C45: - | D45: 0 | E45: 超能力者等級五以上 | F45: 你可以在任何時間點，使自己的HP上限剩下1。在場景結束前可以取得其他級別的任兩個特技(如果有取得條件，則必須滿足)並使用。場景結束前，你的判定增加你的【超能力者等級】。
A46: 幻想之瞳（偽） | B46: 常時 | C46: 最大生命力／２ | D46: 0 | E46: 創造角色時限定獲得 | F46: 你可以取得其他級別任何非額外技能的特技２個。
...

Sheet 武鬥家
A1: 武鬥家
A2: 能力基本值
A3: 體力 | B3: 知覺 | C3: 理智 | D3: 意志
A4: 5 | B4: 2 | C4: 2 | D4: 3
A6: 級別修正表
A7: 等級 | B7: 1 | C7: 2 | D7: 3 | E7: 4 | F7: 5 | G7: 6 | H7: 7 | I7: 8 | J7: 9 | K7: 10
A8: 【近戰】 | B8: 0 | C8: 1 | D8: 4 | E8: 7 | F8: 8 | G8: 9 | H8: 10 | I8: 11 | J8: 12 | K8: 13
A9: 【射撃】 | B9: -1 | C9: 0 | D9: 2 | E9: 3 | F9: 4 | G9: 5 | H9: 6 | I9: 7 | J9: 8 | K9: 9
A10: 【精神】 | B10: -1 | C10: 0 | D10: 2 | E10: 3 | F10: 4 | G10: 5 | H10: 6 | I10: 7 | J10: 8 | K10: 9
A11: 【行動】 | B11: 1 | C11: 2 | D11: 5 | E11: 8 | F11: 9 | G11: 10 | H11: 11 | I11: 12 | J11: 13 | K11: 14
A12: 【生命力】 | B12: 4 | C12: 10 | D12: 16 | E12: 26 | F12: 29 | G12: 31 | H12: 33 | I12: 35 | J12: 37 | K12: 41
A13: 【集中力】 | B13: 5 | C13: 8 | D13: 8 | E13: 11 | F13: 11 | G13: 14 | H13: 16 | I13: 18 | J13: 18 | K13: 21
A14: 【防御點】 | B14: 0 | C14: 1 | D14: 1 | E14: 2 | F14: 2 | G14: 2 | H14: 3 | I14: 3 | J14: 3 | K14: 4
A16: 取得特技 ▲
A17: 初期取得：
A18: 得到「武道」，然後再選擇一個自己喜歡的特技。
A20: 升級：
A21: 等級上升之時、選取一個喜歡的特技。每逢５等、１０等時，可以額外再取得一個特技。
A23: 技能名稱 | B23: 分類 | C23: 代價 | D23: 情緒獎勵 | E23: 取得限制 | F23: 效果
A24: 武鬥家
A25: 一般特技 ▲
A26: 武道 | B26: 常時 | C26: - | D26: 0 | E26: 無 | F26: 你的近戰相關判定常時＋２，傷害＋２。你需要使用【體力】做搜索判定時，達成值＋《２》
A27: 蛇咬 | B27: 攻擊類型／近戰 | C27: - | D27: 2 | E27: 無 | F27: 指定對象一人，給予２Ｄ６傷害。戰鬥中你第一次施放此技能時，命中與傷害＋《４》。
A28: 滲透勁 | B28: 攻撃類型／近戰 | C28: 代價傷害２ | D28: 0 | E28: 無 | F28: 指定對象一人，給予１Ｄ６＋２傷害，此特技實際傷害為一點五倍（去小數點）。
A29: 武心 | B29: 準備階段 | C29: - | D29: 成功時上升2 | E29: 無 | F29: 通過一個目標值為10的2D6+【武鬥家等級】判定。成功則你本回合判定會心下降《１》，全判定上升1，傷害增加《【你的武鬥家等級】》。
A30: 貼打 | B30: 進攻/近戰 | C30: - | D30: 2 | E30: 無 | F30: 實傷後效果，對手下回合結束前不能離開此區域。
A31: 發勁 | B31: 準備階段 | C31: 代價傷害２ | D31: 0 | E31: 無 | F31: 通過一個目標值為10的2D6+【武鬥家等級】判定。成功則你本回合傷害增加《１Ｄ６》。
A32: 破打 | B32: 進攻／近戰 | C32: - | D32: 0 | E32: 無 | F32: 實傷後效果，對手的行動力減去《2D6+3》點，對手因為此特技進入行動完成狀態的話，下個回合無法動作。
A33: 不屈 | B33: 常時 | C33: - | D33: 0 | E33: 無 | F33: 你進入行動不能狀態時，在回合結束為止仍可行動。但是在這期間無法回復ＨＰ以及不良狀態。
A34: 硬氣功 | B34: 防禦 | C34: 代價傷害４ | D34: 0 | E34: 無 | F34: 你的迴避達成值成為１，防禦點＋《４》。
A35: 超反應 | B35: 防禦 | C35: 代價傷害5點 | D35: 0 | E35: 無 | F35: 防禦時，無論攻擊側使用什麼你都能使用【近戰】-4進行迴避判定。
A36: 精神統一 | B36: 準備階段 | C36: - | D36: 0 | E36: 無 | F36: 你每消耗10點TP，就可以恢復《2D6+1》ＨＰ。
A37: 震腳 | B37: 常時 | C37: - | D37: 0 | E37: 無 | F37: 實際傷害後效果，對手的情緒值減去同等傷害骰的數值。
A38: 真氣統合 | B38: 準備階段 | C38: - | D38: 0 | E38: 無 | F38: 你的武鬥家等級必須超過其他級別。 你將現有HP與TP加總後均分。均分後若回復超過原先HP5點，獲得狀態【真氣】。 【真氣】：傷害增加【武鬥家等級】，此回合戰鬥判定增加1D6。狀態持續到你遭受傷害為止。
A39: 額外特技 ▲
A40: 先手必勝 | B40: 通用 | C40: - | D40: 0 | E40: 武鬥家等級4以上 | F40: 通過一個目標值為12的2D6+【武鬥家等級】判定。此次攻擊因為對手技能而進入反擊處理時，你可以跳過命中過程，直接擲傷害骰給予對手傷害。在這之後若對手未進入行動不能狀態，你也受到對手攻擊傷害。
A41: 連環掌 | B41: 通用 | C41: 代價傷害４ | D41: 0 | E41: 武鬥家等級３以上 | F41: 通過一個目標值為12的2D6+【武鬥家等級】判定。成功後蛇咬與滲透勁於實傷階段給予對手《２Ｄ６》傷害。
A42: 合氣投 | B42: 常時 | C42: - | D42: 0 | E42: 武鬥家等級４以上 | F42: 你的破打使對象變成行動完成的狀態時，追加《４Ｄ６》傷害，並可以使對象強制移動到相鄰區域。
A43: 散打 | B43: 通用 | C43: - | D43: 0 | E43: 貼打 | F43: 通過一個目標值為12的2D6+【武鬥家等級】判定。實傷後效果。對象下一次迴避判定時達成值－《４》。
A44: 一擊脫離 | B44: 通用 | C44: 代價傷害10 | D44: 0 | E44: 武鬥家等級4以上 | F44: 通過一個目標值為12的2D6+【武鬥家等級】判定。此次攻擊因為對手技能而進入反擊處理時，你可以選擇降低《2D6》傷害而迴避對手的反擊。對方的待機狀態並不會因此解除。
...

Sheet 古神道
A1: 古神道
A2: 能力基本值
A3: 體力 | B3: 知覺 | C3: 理智 | D3: 意志
A4: 3 | B4: 3 | C4: 3 | D4: 3
A6: 級別修正表
A7: 等級 | B7: 1 | C7: 2 | D7: 3 | E7: 4 | F7: 5 | G7: 6 | H7: 7 | I7: 8 | J7: 9 | K7: 10
A8: 【近戰】 | B8: -1 | C8: 0 | D8: 2 | E8: 3 | F8: 4 | G8: 5 | H8: 6 | I8: 7 | J8: 8 | K8: 9
A9: 【射撃】 | B9: -1 | C9: 0 | D9: 2 | E9: 3 | F9: 4 | G9: 5 | H9: 6 | I9: 7 | J9: 8 | K9: 9
A10: 【精神】 | B10: -1 | C10: 2 | D10: 3 | E10: 4 | F10: 7 | G10: 9 | H10: 11 | I10: 13 | J10: 15 | K10: 17
A11: 【行動】 | B11: -2 | C11: -1 | D11: 0 | E11: 1 | F11: 3 | G11: 4 | H11: 5 | I11: 6 | J11: 7 | K11: 8
A12: 【生命力】 | B12: 0 | C12: 5 | D12: 11 | E12: 17 | F12: 20 | G12: 22 | H12: 24 | I12: 26 | J12: 28 | K12: 30
A13: 【集中力】 | B13: 4 | C13: 6 | D13: 8 | E13: 11 | F13: 14 | G13: 16 | H13: 17 | I13: 18 | J13: 19 | K13: 20
A14: 【防御點】 | B14: 0 | C14: 0 | D14: 0 | E14: 0 | F14: 0 | G14: 0 | H14: 0 | I14: 0 | J14: 0 | K14: 1
A16: 取得特技 ▲
A17: 初期取得：
A18: 得到「陰陽道」、「五名門」。
A20: 升級：
A21: 等級上升之時、選取一個喜歡的特技。每逢５等、１０等時，可以額外再取得一個特技。
A23: 技能名稱 | B23: 分類 | C23: 代價 | D23: 情緒獎勵 | E23: 取得限制 | F23: 效果
A24: 古神道
A25: 一般特技 ▲
A26: 陰陽道 | B26: 常時 | C26: - | D26: 0 | E26: 無 | F26: 你得到這個屬性。可以重複藉著這個特技獲得屬性。 使用古神道技能時，減少你的【陰陽道等級】詠唱時間。對全屬性抗性為【(陰陽道等級/2)+1】。 你的ＴＰ上限額外增加【陰陽道等級Ｘ１０】，每日結束時恢復最大值十分之一。 在魔力的有無及強弱的感知檢定的【知覺】判定達成値上＋《３》。
A27: 五名門 | B27: 常時 | C27: - | D27: 0 | E27: 無 | F27: 你的古神道等級必須超過其他級別。 你的最大HP、TP+10，「陰陽道」技能+1，《》內的數值+1。戰鬥以外的判定常時+1。
A28: 符 | B28: 攻撃類型／射擊 | C28: 待機延遲4，代價傷害4 | D28: 0 | E28: 無 | F28: 指定對象一個人、給予《2D6點+【陰陽道等級】》的傷害。 使用這特技時，命中會額外增加【你的陰陽道等級】。 使用此技能需要陰陽道等級一以上。
A29: 斬魔刀 | B29: 攻撃類型／近戰 | C29: - | D29: 0 | E29: 無 | F29: 指定對象一個人，然後給予2D6+【陰陽道等級】的傷害。 傷害擲骰的結果12點以上追加《1》D6的傷害。 使用此技能需要陰陽道等級一以上。
A30: 結界鋪設 | B30: 通常 | C30: 代價傷害20 | D30: 0 | E30: 無 | F30: 將你所持有的一個特技做為對象。將該對象「設置」。 被設置的特技、可以在設置的地點不支付代價而使用。 可以設置的特技個數上限、跟你的古神道等級相同。 預置結界有被發現而遭破壞可能，耐久度為你的2D6+古神道等級+精神。 執行破壞結界行動時，一律為2D6+玩家精神 戰鬥中無法使用。
A31: 封印結界 | B31: 準備階段 | C31: 代價傷害20 | D31: 0 | E31: 無 | F31: 做出【你的古神道等級】個人或物無法逃脫的領域。 結界的基礎封印能力依你的古神道等級而定。 LV1~3:9~11 LV4~6:12~14 LV7~9:15~17 超過十級以此類推。總值為(基礎封印能力+【陰陽道等級】) 在結界範圍內給予下列所有效果： 被指定的人要從範圍內離開時須進行精神抵抗，失敗的話即無法離開。 在戰鬪中則每回合可嘗試一次。 被指定的人或物，從範圍內向範圍外的近戰攻擊，因屬於脫逃所以要進行精神抵抗，若未能成功即無法進行。成功的話，即可從結界中脫離。抵抗公式為2D6+精神。 範圍內向外的遠戰攻擊視同執行破壞結界行動，每回合可執行一次， 執行破壞結界行動時，一律為2D6+玩家精神 結界耐久度為你的《2D6》+基礎封印能力+古神道等級+精神
A32: 式神 | B32: 準備階段 | C32: 代價傷害10 | D32: 0 | E32: 陰陽道等級三以上 | F32: 喚出一體式神，能力參考鬼神。 能招換的數量為〈(【你的古神道等級】+【你的陰陽道等級】)/2〉
A33: 集中 | B33: 準備階段 | C33: 代價傷害15 | D33: 0 | E33: 陰陽道等級二以上 | F33: 你的命中與迴避的達成值增加【精神】/4。 結束階段時，通過難易度20的精神骰後，不需支付代價可以維持。
A34: 二刀流 | B34: 進攻／近戰 | C34: 待機延遲3 | D34: 2 | E34: 陰陽道等級二以上 | F34: 搭配斬魔刀使用可合算為單一特技，以你攻擊對象的角色發揮效果。 這是實際傷害後效果。你可以再次擲傷害骰、給與對方傷害。 但是如果這攻擊是全體攻擊，無法發揮此技能效果。
A35: 祈禱之加持 | B35: 準備階段／結束階段 | C35: 代價傷害10 | D35: 0 | E35: 陰陽道等級一以上 | F35: 回覆一名目標生物ＨＰ《2》D6+【你的陰陽道等級】的治癒術。並恢復一個不良狀態。
A36: 淨身 | B36: 中斷 | C36: 行動點10點 | D36: 你的陰陽道等級 | E36: 陰陽道等級一以上 | F36: 對象進行判定前使用，藉由給予祝福，對象本次判定達成值加上【你的陰陽道等級】。
A37: 額外特技 ▲
A38: 式神憑依 | B38: 通常 | C38: - | D38: 0 | E38: 陰陽道等級三以上、式神 | F38: 將召喚出的一體式神憑依至自己身上。大幅提高戰鬥能力。 把式神的全數值加到自己身上，這個數值不能超過你的《【陰陽道】》等級。 HP或TP歸零時此狀態解除。 在此狀態時每經過一次行動，得付出代價傷害10點-你的【陰陽道】等級。
A39: 血之刻印 | B39: 常時 | C39: - | D39: 0 | E39: 陰陽道等級一以上 | F39: 你的防禦常時+《1》。藉由刻印的封印之術，能夠把不易攜帶的武器或物品藏入奇特的空間之中。物體大小限制為你的【陰陽道等級】m。
A40: 五行破魔 | B40: 進攻／射擊 | C40: 待機延遲10 | D40: 0 | E40: 陰陽道等級三以上 | F40: 此技能需要配合符技能使用。 給予一名敵人增加《【你的陰陽道等級】》D6 的攻擊，實際傷害為兩倍。此攻擊為類概念武裝。
A41: 天地陰陽 | B41: 常時 | C41: 待機延遲5點，代價傷害10 | D41: 0 | E41: 陰陽道等級三以上、血之刻印 | F41: 此技能需要擁有血之刻印技能才能作用。 你的古神道技能傷害增加《【你的陰陽道等級】》點。
A42: 神護 | B42: 常時 | C42: - | D42: 0 | E42: 陰陽道等級二以上 | F42: 你受到的傷害減少三分之二。而後受到等同傷害的代價傷害。
A43: 破魔結界 | B43: 通常 | C43: 代價傷害50 | D43: 0 | E43: 陰陽道等級三以上 | F43: 此技能需要擁有封印結界技能，並該技能為發動中才能使用。 在範圍內可解除運作中的能力效果，更可使範圍內的能力難以運作。 在結界範圍內依造順序給予下列全部效果。 ► 啟動後解除封印結界。 ► 瞬間給予結界內不分敵我全部人物5D6+10+ 【你的陰陽道等級】+精神的傷害。 如果其中有使魔、死徒、擁有背反律「死之転生」或「反轉衝動」、技能「於世所不容者」者、或者是背反者，需再承受一次傷害。 ► 給予結界內不分敵我全部人物持有之特殊狀態全部解除。 ► 結界內不分敵我全部人物之能力值全部下降【你的陰陽道等級】點，效果持續【你的陰陽道等級】回合。 ► 此結界解除。 使用後你的情緒值無論剩餘多少瞬間歸零。使用時TP須為1以上。

Sheet 魔術師
A1: 魔術師
A2: 能力基本值
A3: 體力 | B3: 知覺 | C3: 理智 | D3: 意志
A4: 2 | B4: 3 | C4: 5 | D4: 2
A6: 級別修正表
A7: 等級 | B7: 1 | C7: 2 | D7: 3 | E7: 4 | F7: 5 | G7: 6 | H7: 7 | I7: 8 | J7: 9 | K7: 10
A8: 【近戰】 | B8: -1 | C8: 0 | D8: 1 | E8: 2 | F8: 3 | G8: 4 | H8: 5 | I8: 6 | J8: 7 | K8: 8
A9: 【射撃】 | B9: 0 | C9: 1 | D9: 2 | E9: 3 | F9: 6 | G9: 8 | H9: 10 | I9: 12 | J9: 14 | K9: 16
A10: 【精神】 | B10: 0 | C10: 1 | D10: 2 | E10: 3 | F10: 6 | G10: 8 | H10: 10 | I10: 12 | J10: 14 | K10: 16
A11: 【行動】 | B11: -1 | C11: 0 | D11: 1 | E11: 2 | F11: 3 | G11: 4 | H11: 5 | I11: 6 | J11: 7 | K11: 8
A12: 【生命力】 | B12: 0 | C12: 3 | D12: 9 | E12: 15 | F12: 20 | G12: 22 | H12: 24 | I12: 26 | J12: 28 | K12: 30
A13: 【集中力】 | B13: 8 | C13: 11 | D13: 13 | E13: 15 | F13: 17 | G13: 20 | H13: 23 | I13: 26 | J13: 28 | K13: 30
A14: 【防御點】 | B14: 0 | C14: 0 | D14: 0 | E14: 0 | F14: 0 | G14: 0 | H14: 0 | I14: 0 | J14: 0 | K14: 1
A16: 取得特技 ▲
A17: 初期取得：
A18: 得到「魔術迴路」、然後再選擇一個自己喜歡的特技。
A20: 升級：
A21: 等級上升之時、選取一個喜歡的特技。每逢５等、１０等時，可以額外再取得一個特技。
A23: 技能名稱 | B23: 分類 | C23: 代價 | D23: 情緒獎勵 | E23: 取得限制 | F23: 效果
A24: 魔術師
A25: 一般特技 ▲
A26: 魔術迴路 | B26: 常時 | C26: - | D26: 0 | E26: 無 | F26: 你的ＴＰ上限增加【魔術師等級*10】，每日結束時恢復最大值十分之一。你持有一屬性，屬性值會依據你的魔術師等級而有所增加。一等為2，爾後每等上升1。你在魔力感知的判定常時+2。使用魔術師技能時，你的達成值額外增加【精神】／4。 你需要使用【意志】做情報判定時，達成值＋《２》。 ※在角色創造時，你每減少一等級，便可以多獲得一種屬性。以三等角色為例，最多可以減少兩等多獲得兩種屬性，以等級一角色開始。
A27: 思考的並列演算 | B27: 中斷 | C27: 代價傷害２ | D27: 1 | E27: 無 | F27: 在你行為判定之後使用，達成值＋１Ｄ６(這個數值不能超過你的魔術師等級)，使用後行動值－４。
A28: 靈子光纖 | B28: 攻擊類型／射擊 | C28: 代價傷害2 | D28: 0 | E28: 無 | F28: 指定一對象給予２Ｄ６傷害，命中後對象獲得不良狀態「鎖定」。 此不良狀態可以疊加。 【鎖定】：當你受到來自鎖定者的攻擊時，鎖定者的命中判定+3，會心-1。
A29: 靈子標記 | B29: 準備階段 | C29: 代價傷害5 | D29: 0 | E29: 無 | F29: 指定一對象給予不良狀態「鎖定」。 【鎖定】：當你受到來自鎖定者的攻擊時，鎖定者的命中判定+3，會心-1。
A30: 靈子散射 | B30: 進攻／通常 | C30: - | D30: 0 | E30: 無 | F30: 本次攻擊的對象成為所有遭受你鎖定之人。鎖定對象每增加1人，傷害減少1D6(不會減少到2D6以下)。
A31: 防禦結界 | B31: 準備階段 | C31: 代價傷害15 | D31: 0 | E31: 無 | F31: 因應你的屬性，展開保護自己的防禦式。若持有多種屬性，會同時發動。 結束階段需付出10點的代價傷害維持效果。 ►地：你增加三點防禦。 ►水：攻擊側的傷害減少1D6。 ►風：你增加三點迴避判定。 ►空：你的迴避會心下降2。 ►其他：請洽GM。
A32: 強化 | B32: 準備階段 | C32: 代價傷害10 | D32: 0 | E32: 無 | F32: 以同區域角色1人所持武器、或是分類：攻擊類型技能為對象。傷害＋《４》，並具有概念武裝效果。此效果持續到結束階段。在施放時，你可以以每回合5點的代價傷害將這個技能的效果回合數延長。
A33: 咒怨彈 | B33: 攻擊類型／射擊 | C33: 代價傷害5 | D33: 0 | E33: 無 | F33: 指定對象1人，給予2D6+【理智】點傷害。此技能使用後，你減少7點行動點，並且不會進入已行動狀態。 實傷後效果，對手下回合全判定-《1》。此傷害需扣減對象的最高屬性值。
A34: 魔術刻印 | B34: 常時 | C34: - | D34: 0 | E34: 無 | F34: 你的魔術使用代價輕減四分之一（包含待機延遲）。你的ＴＰ額外增加５０點上限，每到準備階段，你會恢復［你的魔術師等級Ｘ３］點ＴＰ。每到結束階段，你會恢復［你的魔術師等級］ＨＰ。
A35: 使魔 | B35: 常時 | C35: - | D35: 0 | E35: 無 | F35: 你擁有共享五感的使魔。使魔的能力可以從「狗」、「烏鴉」、「灰貓」任選一。你可以重複取得此特技，使魔死亡的話會於下個劇本或是在戰鬥外支付30點代價傷害復活。
A36: 共感 | B36: 常時 | C36: - | D36: 0 | E36: 無 | F36: 以角色一人為對象，你取得對象的五感。此效果須經對方同意。將此技能以無盡破壞使用時，你可以在複製對象的能力值為己所用，每到回合結束必須支付５０點ＴＰ以持續效果。
A37: 禮裝所持 | B37: 常時 | C37: - | D37: 0 | E37: 無 | F37: 你得到一個魔術禮裝，此特技可以重複取得。
... A54: 無息詠唱 | B54: 準備階段 | C54: 代價傷害5、行動點數4 | D54: 0 | E54: 無 | F54: 和魔術師特技一起宣言，會產生以下效果： ►這回合你使用的魔術師特技待機延遲減少《2》，你的行動點數減少《》內值的1.5倍。 ►和『防禦結界』組合時，『防禦結界』使用代價以及維持代價減半。 ►持有【空屬性】時，效果文中《》內的數值+2，【空屬性】大於等於５時，再+2。 ►一戰鬥可以使用【１＋[你的魔術師級別等級／4]】回使用。 ►不能和其他名稱中有【詠唱】的特技同時使用，不能作為無盡破壞的對象。
A55: 額外特技 ▲
A56: 結界鋪設 | B56: 通常 | C56: 代價傷害20 | D56: 0 | E56: 魔術師等級2以上 | F56: 將你所持有的一個特技做為對象。將該對象「設置」。被設置的特技、可以在設置的地點不支付代價而使用。 可以設置的特技個數上限、跟你的魔術師等級相同。 預置結界有被發現而遭破壞可能，耐久度為你的《2D6》+魔術師等級+(精神/3)。 執行破壞結界行動時，一律為(2D6+玩家精神/3)。 戰鬥中無法使用。
A57: Fin之一擊 | B57: 進攻／射擊 | C57: 代價傷害20點 | D57: 0 | E57: 咒怨彈、魔術師等級5以上 | F57: 搭配咒怨彈使用，此次傷害增加《５Ｄ６》，實傷後效果，當對手因此次攻擊HP至0以下時，直接死亡。
A58: 複數詠唱 | B58: 進攻／射擊 | C58: 代價傷害30點，待機延遲10點 | D58: 0 | E58: 詠唱、魔術師等級6以上 | F58: 此技能需要配合詠唱技能使用。你的詠唱傷害追加「１Ｄ６＋［你所有不為零以下屬性的總和］」，每多一種屬性，待機延遲增加等量屬性點。此技能使用時，行動點數不可小於你所需的待機延遲點數。
A59: 人偶專精 | B59: 常時 | C59: - | D59: 0 | E59: 魔術師等級4以上 | F59: 你每日能製造的人偶數目+1。你的人偶抵擋傷害成為15+【魔術師等級】點。
A60: 自我複製 | B60: 常時 | C60: - | D60: 0 | E60: 人偶專精、魔術師等級8以上 | F60: 一劇本一次，當你死亡時，於下一個場景復活，戰鬥中在三回合後復活。
...

Sheet 異端
A1: (級別)
A2: 能力基本值
A3: 體力 | B3: 知覺 | C3: 理智 | D3: 意志
A4: 4 | B4: 2 | C4: 2 | D4: 4
A6: 級別修正表
A7: 等級 | B7: 1 | C7: 2 | D7: 3 | E7: 4 | F7: 5 | G7: 6 | H7: 7 | I7: 8 | J7: 9 | K7: 10
A8: 【近戰】 | B8: 1 | C8: 1 | D8: 2 | E8: 2 | F8: 3 | G8: 4 | H8: 5 | I8: 6 | J8: 7 | K8: 8
A9: 【射撃】 | B9: 1 | C9: 1 | D9: 2 | E9: 2 | F9: 3 | G9: 4 | H9: 5 | I9: 6 | J9: 7 | K9: 8
A10: 【精神】 | B10: 1 | C10: 1 | D10: 2 | E10: 2 | F10: 3 | G10: 4 | H10: 5 | I10: 6 | J10: 7 | K10: 8
A11: 【行動】 | B11: 1 | C11: 1 | D11: 2 | E11: 2 | F11: 2 | G11: 3 | H11: 4 | I11: 5 | J11: 6 | K11: 7
A12: 【生命力】 | B12: 3 | C12: 5 | D12: 8 | E12: 10 | F12: 11 | G12: 13 | H12: 15 | I12: 18 | J12: 21 | K12: 24
A13: 【集中力】 | B13: 3 | C13: 5 | D13: 8 | E13: 10 | F13: 11 | G13: 13 | H13: 15 | I13: 18 | J13: 21 | K13: 24
A14: 【防御點】 | B14: 0 | C14: 1 | D14: 1 | E14: 1 | F14: 2 | G14: 2 | H14: 2 | I14: 3 | J14: 3 | K14: 4
A16: 取得特技 ▲
A17: 初期取得：
A18: 得到「架空存在」、或是「理外存在」。
A20: 升級：
A21: 每當等級是2的倍數時，你可以取得兩個特技。當等級是三等、七等時，你可以取得一個特技
A23: 技能名稱 | B23: 分類 | C23: 代價 | D23: 情緒獎勵 | E23: 取得限制 | F23: 效果
A24: 異端
A25: 一般特技 ▲
A26: 架空存在 | B26: 常時 | C26: - | D26: 0 | E26: 無 | F26: 你的屬性空+《3》，其他屬性-《2》。
A27: 理外存在 | B27: 常時 | C27: - | D27: 0 | E27: 無 | F27: 劇本開始時，你的【生命力】與【集中力】+3D6。
A28: 虛數破壞 | B28: 攻擊類型／特殊 | C28: 代價傷害2 | D28: 1D6 | E28: 無 | F28: 對一人發動傷害是《2D6》的攻擊。 攻擊時丟出1D6，「1、2」此攻擊為近戰，「3、4」為遠戰，「5、6」為精神。 此攻擊只能與分類共通的特技組合。
A29: 屬性顯現 | B29: 進攻類型／共通 | C29: 代價傷害3 | D29: 2 | E29: 無 | F29: 取得此特技時決定一個屬性。發動此特技時，攻擊成為該屬性，並傷害追加該屬性數值。
A30: 對物理能力 | B30: 常時 | C30: - | D30: 0 | E30: 無 | F30: 非概念武裝或是上限傷害的傷害減少《1D6》。
A31: 對魔術能力 | B31: 常時 | C31: - | D31: 0 | E31: 無 | F31: 概念武裝或是上限傷害的傷害減少《1D6》。
A32: 攻性概念 | B32: 常時 | C32: - | D32: 0 | E32: 無 | F32: 當你只擁有異端級別時，傷害+《異端等級》，攻擊成為概念武裝。
A33: 妨害工作 | B33: 中斷 | C33: 代價傷害2 | D33: 1 | E33: 無 | F33: 全區域任何人判定時使用，對象達成值-《1D6》，使用後自己行動值減少1D6。
A34: 高昂 | B34: 常時 | C34: - | D34: 0 | E34: 無 | F34: 準備階段時，TP+《異端等級》。結束階段時，HP+《異端等級》
A35: 能力上升 | B35: 準備階段 | C35: 代價傷害3 | D35: 2 | E35: 無 | F35: 對同區域一人使用。 到戰鬥結束為止，HP與TP之外的戰鬥能力值選一項+《1D6》。但是，受到使用的對象將每回合結束時受到《1D6》的實際傷害。 此效果可以累加。 對象如要抵抗，以精神骰判定。
A36: 三稜鏡之骰 | B36: 中斷 | C36: 代價傷害5 | D36: 1D6 | E36: 無 | F36: 一劇本只能發動三次。 這個特技宣言後，自己下一個所使用的特技的攻擊對象數會擴大1D6。無論原本攻擊類型射程為何，都可以攻擊選中的對象。但是，丟出6的話等同於0。 另外丟出的數目也一定得全部選完對象。不選的話，必須受到「沒有選擇人數*異端等級」點的無視防禦實際傷害。
A37: 天啟 | B37: 通用 | C37: - | D37: 1D6 | E37: 無 | F37: 一劇本只能發動兩次。 對GM詢問一個問題，GM必須告訴你是或否。 或是重骰一個自己的判定。
A38: 常識外的倔強 | B38: 常時 | C38: - | D38: 0 | E38: 異端LV3以上 | F38: 你受到的傷害常時減輕《1》D6。以你自己為對象， 每回合結束時HP跟情緒值+《1》D6。
A39: U的意志 | B39: 常時 | C39: - | D39: 0 | E39: 創角時取得 | F39: 你的角色名稱必須有U或優字。 當你的級別只有異端時，你可以擁有兩個風格。
A40: 額外特技 ▲
A41: 戲謔者 | B41: 中斷 | C41: 代價傷害5 | D41: 2 | E41: 異端LV3以上 | F41: 一場戰鬥只能使用一次。 讓全區域內一人的判定自動失敗。但是下一個自己的判定也必定失敗。
A42: 也許會有這種好事 | B42: 中斷 | C42: - | D42: 0 | E42: 異端LV4以上 | F42: 一劇本只能使用一次。 當你只擁有異端級別時，可以發揮以下效果： 當你受到攻擊時，可以放棄迴避骰，將受到的一半傷害隨機轉給你以外的人。
A43: 例外存在 | B43: 常時 | C43: - | D43: 0 | E43: 異端LV4以上 | F43: 你所有異端特技《》數值+2。
A44: 秘密兵器 | B44: 常時 | C44: - | D44: 0 | E44: 異端LV5以上 | F44: 劇本開始時，不管種類，可以入手一道具。如果需要職業等級以《3》計算。 劇本中只能使用一次，不管種類，可以瞬間獲得一道具。如果需要職業等級以《3》計算。 取得的道具在換景時消失，戰鬥的話回合結束時消失。
...

Sheet 左道
A1: 左道
A2: 能力基本值
A3: 體力 | B3: 知覺 | C3: 理智 | D3: 意志
A4: 2 | B4: 3 | C4: 2 | D4: 5
A6: 級別修正表
A7: 等級 | B7: 1 | C7: 2 | D7: 3 | E7: 4 | F7: 5 | G7: 6 | H7: 7 | I7: 8 | J7: 9 | K7: 10
A8: 【近戰】 | B8: -1 | C8: -1 | D8: 0 | E8: 1 | F8: 5 | G8: 6 | H8: 7 | I8: 8 | J8: 10 | K8: 11
A9: 【射撃】 | B9: -1 | C9: -1 | D9: 0 | E9: 1 | F9: 5 | G9: 7 | H9: 9 | I9: 10 | J9: 12 | K9: 14
A10: 【精神】 | B10: 0 | C10: 0 | D10: 1 | E10: 2 | F10: 5 | G10: 7 | H10: 9 | I10: 10 | J10: 11 | K10: 12
A11: 【行動】 | B11: 0 | C11: 1 | D11: 1 | E11: 4 | F11: 8 | G11: 10 | H11: 11 | I11: 12 | J11: 13 | K11: 14
A12: 【生命力】 | B12: 0 | C12: 0 | D12: 5 | E12: 10 | F12: 15 | G12: 17 | H12: 20 | I12: 23 | J12: 26 | K12: 29
A13: 【集中力】 | B13: 5 | C13: 5 | D13: 5 | E13: 10 | F13: 15 | G13: 20 | H13: 25 | I13: 28 | J13: 31 | K13: 34
A14: 【防御點】 | B14: 0 | C14: 0 | D14: 0 | E14: 0 | F14: 1 | G14: 1 | H14: 1 | I14: 2 | J14: 2 | K14: 2
A16: 取得特技 ▲
A17: 初期取得：
A18: 選擇兩個自己喜歡的特技。
A20: 升級：
A21: 等級上升之時、選取一個喜歡的特技。3、6、9級，可以取得兩個特技。
A23: 技能名稱 | B23: 分類 | C23: 代價 | D23: 情緒獎勵 | E23: 取得限制 | F23: 效果
A24: 左道
A25: 一般特技 ▲
A26: 隨選武器 | B26: 攻擊類型/近戰 | C26: - | D26: 0 | E26: 無 | F26: 當你沒有其他攻擊類型時，你以能夠隨手抄起的物品作為武器，給予對象《2D6》點傷害。攻擊之後該物品無法再使用。這個技能無法作反擊使用。
A27: 意外襲擊 | B27: 進攻／共通 | C27: 代價傷害4 | D27: 0 | E27: 無 | F27: 一個場景一次，使用未曾用過的攻擊類型時，命中與傷害增加《1D6》。
A28: 混亂戰術 | B28: 通用 | C28: 代價傷害10 | D28: 0 | E28: 無 | F28: 自己設定一個合理的方式，製造出《1D6+1》個人在做些什麼行動的錯覺，混亂他人。錯覺的位置不限於你所在的場景，但需取得GM的同意。由於只是「好像有人在行動」的錯覺，不會因此達成什麼行為。 一般情形下效果持續到時間段轉換，特殊場景中持續到場景終了。戰鬥中無法使用。
A29: 內部情報 | B29: 常時 | C29: - | D29: 10（推論正確時） | E29: 無 | F29: 一劇本[左道等級/2]次，你能得知一個假設的對或錯。
A30: 反向推論 | B30: 常時 | C30: - | D30: 0 | E30: 無 | F30: 當你在「混亂戰術」效果期間，進行搜查/情報判定時，可以指定自己所在地以外的場景。
A31: 應急處置 | B31: 中斷 | C31: 代價傷害5 | D31: 0 | E31: 無 | F31: 一個劇本可以使用[你的左道等級]次，指定同區域一個角色，消去該角色的一個狀態。
A32: 同行者 | B32: 常時 | C32: - | D32: 0 | E32: 無 | F32: 指定一個你放置兩個白色感情的對象（或者劇情發展上相當且GM同意的對象），一起行動時你的達成值+2。 你可以更換此技能的對象，但是同時最多只有[你的左道等級/2]人。效果不會累加。你可以再取得一個同行者相關的技能。
A33: 牽制攻擊 | B33: 進攻／共通 | C33: - | D33: 5 | E33: 無 | F33: 當你在同行者之前攻擊時，你本次命中必定失敗，同行者的達成值+4。
A34: 戰術分配 | B34: 進攻／共通 | C34: 代價傷害2點 | D34: 0 | E34: 無 | F34: 當你接在同行者下一個行動，且使用不同命中判定的攻擊類型，達成值+2。
A35: 聲東擊西 | B35: 進攻／共通 | C35: 代價傷害2點 | D35: 0 | E35: 無 | F35: 當你與同行者同時攻擊(或同行動點進行攻擊)時，同行者的達成值+2。
A36: 亂戰脫離 | B36: 特殊 | C36: - | D36: 5 | E36: 無 | F36: 這個技能不是攻擊類型，但以攻擊類型的方式使用。當你以此技能對複數攻擊宣言反擊且成功時、或者緊接複數攻擊下一個行動使用時，通過12-《知覺》的體力判定可以馬上逃離戰鬥。反擊時以你最高的戰鬥值作命中判定。
A37: 戰術轉進 | B37: 中斷 | C37: - | D37: 5 | E37: 無 | F37: 使用亂戰脫離時可發動，你可以帶同行者一同逃跑，每一個同行者判定難度+2。
A38: 立體地圖 | B38: 常時 | C38: 代價5TP（準備階段） | D38: 5 | E38: 無 | F38: 你懂得使用他人無法行走之路徑的技巧，地圖移動時時間縮短為50%。在準備階段使用時，你可以增加5點行動或3點逃跑達成值，但一次只能選一個使用。選擇逃跑時，無法和戰術轉進一起使用。
A39: 隱藏武器 | B39: 常時 | C39: - | D39: 5（使用攻擊類型命中時） | E39: 無 | F39: 指定一個攻擊類型，視為不存在，你能指定的數量為[你的左道等級/2]個。 當你第一次使用該攻擊類型時，命中+1D6，並失去隱藏武器的效果，此後無法再隱藏。 此技能無法與隨選武器和現地改造搭配使用。
A40: 竊聽 | B40: 通常 | C40: 代價傷害10 | D40: 0 | E40: 無 | F40: 指定一個密閉環境（上下四方有牆，但不必是密室狀態），設置一個竊聽裝置，你能同時設置[你的左道等級/3]個。 設置時擲《2D6+[你的左道等級]+[理智]》作為基本值，察覺的判定為對方的知覺對抗你的基本值。
A41: 常住戰陣 | B41: 常時 | C41: - | D41: 0 | E41: 無 | F41: 你所有技能中使用左道等級計算的項目，以等級+2去計算。
A42: 額外特技 ▲
A43: 超加速 | B43: 中斷 | C43: 代價傷害20 | D43: 0 | E43: 左道等級3以上 | F43: 一個場景一次。 戰鬥中你可以從任意區域對敵方後排進行攻擊，並在攻擊結束後回到任意區域。 如你在相同場景但不在戰鬥之中，你可以立刻加入戰鬥對敵方後排進行攻擊，並在攻擊結束後回到任意區域。 如須判定距離，原則上為一次行動能移動的距離，如有取得立體地圖，移動距離為兩倍。
A44: 對人陷阱 | B44: 通用 | C44: 代價傷害10 | D44: 0 | E44: 左道等級3以上，取得竊聽。 | F44: 指定一個密閉環境（上下四方有牆，但不必是密室狀態），設置一個對人陷阱，當他人進入此空間時發動，造成《2D6+ [你的左道等級/2]》的傷害，你能同時設置[你的左道等級/3]個。 設置時擲《2D6+[你的左道等級]+[理智]》作為基本值，察覺的判定為對方的知覺對抗你的基本值。
...

Sheet 策士
A1: 策士
A2: 能力基本值
A3: 體力 | B3: 知覺 | C3: 理智 | D3: 意志
A4: 1 | B4: 4 | C4: 4 | D4: 3
A6: 級別修正表
A7: 等級 | B7: 1 | C7: 2 | D7: 3 | E7: 4 | F7: 5 | G7: 6 | H7: 7 | I7: 8 | J7: 9 | K7: 10
A8: 【近戰】 | B8: 0 | C8: 0 | D8: 0 | E8: 0 | F8: 0 | G8: 0 | H8: 0 | I8: 0 | J8: 0 | K8: 0
A9: 【射撃】 | B9: 0 | C9: 0 | D9: 0 | E9: 0 | F9: 0 | G9: 0 | H9: 0 | I9: 0 | J9: 0 | K9: 0
A10: 【精神】 | B10: 0 | C10: 0 | D10: 0 | E10: 0 | F10: 0 | G10: 0 | H10: 0 | I10: 0 | J10: 0 | K10: 0
A11: 【行動】 | B11: 0 | C11: 0 | D11: 0 | E11: 0 | F11: 0 | G11: 0 | H11: 0 | I11: 0 | J11: 0 | K11: 0
A12: 【生命力】 | B12: 0 | C12: 0 | D12: 0 | E12: 0 | F12: 0 | G12: 0 | H12: 0 | I12: 0 | J12: 0 | K12: 0
A13: 【集中力】 | B13: 0 | C13: 0 | D13: 0 | E13: 0 | F13: 0 | G13: 0 | H13: 0 | I13: 0 | J13: 0 | K13: 0
A14: 【防御點】 | B14: 0 | C14: 0 | D14: 0 | E14: 0 | F14: 0 | G14: 0 | H14: 0 | I14: 0 | J14: 0 | K14: 0
A16: 取得特技 ▲
A17: 初期取得：
A18: 選擇兩個自己喜歡的特技。
A20: 升級：
A21: 等級上升之時、選取一個喜歡的特技。每逢3等、6等、9等時，可以額外再取得一個特技。
A23: 技能名稱 | B23: 分類 | C23: 代價 | D23: 情緒獎勵 | E23: 取得限制 | F23: 效果
A24: 策士
A25: 一般特技 ▲
A26: 可造之材 | B26: 常時 | C26: - | D26: 0 | E26: 創角時獲得、策士等級三以上 | F26: 劇本開始前，你獲得等同於【策士等級】的數值。 你可以自由分配該數值到近戰、射擊、精神、行動。 分配的數值不會因為劇本結束而消失。
A27: 朽木可雕 | B27: 常時 | C27: - | D27: 0 | E27: 創角時獲得、策士等級二以上 | F27: 劇本開始前，你獲得等同於【策士等級】的數值。 你可以自由分配該數值到基本能力值(非紅利)。
A28: 佈局 | B28: 常時 | C28: - | D28: 0 | E28: 無 | F28: 劇本開始前，你獲得等同於【策士等級+1】的數值。 每一點數值可以讓你在一個地區散撥一則訊息。 散撥的訊息無法被追蹤源頭。
A29: 觀察眼 | B29: 常時 | C29: - | D29: 0 | E29: 無 | F29: 你在戰鬥以外【理智】上的判定獲得+3。 戰鬥中有人施展技能並發揮效果後，你可以得知其技能效果。 當有人受到攻擊傷害後，你可以得知其生命剩餘百分比。
A30: 戰場指揮 | B30: 準備階段 | C30: - | D30: 2 | E30: 無 | F30: 在我方戰鬥成員兩名以上時可以使用。 你可以任意調配我方成員至前排與後排(須符合阻礙規則)。
A31: 智者不惑 | B31: 常時 | C31: - | D31: 0 | E31: 無 | F31: 你的知覺與理智判定＋３。 當你得知的情報來自於有心人士散撥，或是【佈局】時，做一個2D6+【策士等級】的對抗骰。 對抗成功的話，可以知道情報是被刻意散撥。
A32: 愚者千慮 | B32: 常時 | C32: - | D32: 0 | E32: 無 | F32: 一劇本可以使用一次。 下個判定增加你的【策士等級】數值，若判定失敗，可繼續使用此技能。
A33: 錦囊妙計 | B33: 常時 | C33: - | D33: 0 | E33: 無 | F33: 劇本開始前，你獲得等同於【正面感情絆值／２】的錦囊。錦囊為消耗品，可贈與他人。但必須你不在同一場景才可使用。劇本結束後即消失。 錦囊效果如下： 使用者在下一個判定增加你的【策士等級】數值。 戰鬥中可以得知一名敵人的戰鬥數值。
A34: 奇門遁甲 | B34: 常時／通用 | C34: - | D34: 0 | E34: 無 | F34: 在戰鬥以外的判定丟出大失敗時，將大失敗效果取消，其值加上你的【策士等級】數值。這個效果一天只能發動一次。 在GM認為可以逃跑的戰鬥中，於準備階段支付15點TP使用，你從戰鬥場景離開，且無法被追蹤。
A35: 情報網 | B35: 常時 | C35: - | D35: 0 | E35: 無 | F35: 指定【策士等級-2】區域，如果有發生狀況你會得知。 你不必親自抵達該區域。
A36: 六壬神課 | B36: 常時 | C36: - | D36: 0 | E36: 無 | F36: 在戰鬥以外的判定丟出大失敗時，將大失敗效果取消，再骰一次。這個效果一天只能發動你的【策士等級】次。 在GM認為可以逃跑的戰鬥中，你逃跑判定獲得【策士等級】的加值。
A37: 太乙神數 | B37: 常時 | C37: - | D37: 0 | E37: 無 | F37: 在戰鬥以外的判定會心減3。這個效果一天只能發動你的【策士等級】次。 在GM認為可以逃跑的戰鬥中，你可以多帶【策士等級】的人一起離開。
A38: 額外特技 ▲
A39: 諸子百家 | B39: 常時 | C39: - | D39: 0 | E39: 策士等級四以上 | F39: 你師承名門，「可造之材」與「朽木可雕」的效果額外加一。 戰鬥中，你的傷害額外增加你的【策士等級】。 你的「佈局」效果增加： 每兩點數值指定一個區域，當該區域發生戰鬥時，以下效果擇一發動： 敵方全體HP、TP減少三分之一。 敵方全體受到1D6的隨機不良狀態。 敵方全體判定減少1D6(發動瞬間固定此數值)。
A40: 計中計局中局 | B40: 常時 | C40: - | D40: 0 | E40: 佈局 | F40: 你的「佈局」效果增加： 每兩點數值指定一個區域，該區域若已被佈局戰鬥效果，將該效果對象反轉為敵方全體，或是直接破壞佈局。
A41: 化身 | B41: 常時 | C41: - | D41: 0 | E41: 絕智奇才、可造之材、朽木可雕 | F41: 你的HP、TP額外增加【策士等級】*5。 劇本開始前，你可以獲得等同【目前技能數目-2】的其他級別技能，但必須滿足取得限制。 當你進入行動不能狀態時，取得的其他級別技能全部捨棄，你的HP包含上限傷害，一併恢復到最大值。
A42: 神謀鬼算 | B42: 常時 | C42: - | D42: 0 | E42: 智者不惑、錦囊妙計 | F42: 一劇本一次，你可以就角色手頭得知的情報，組織邏輯推述給GM詢問一件事。 GM必須回答你正確或錯誤，如果錯誤，必須指出問題點或附贈相關情報。
A43: 縱橫連環 | B43: 常時 | C43: - | D43: 0 | E43: 情報網、策士等級三以上 | F43: 劇本開始前，你可以清楚了解劇本內所有勢力以及登場人物的公開情報。 如果有隱藏未明的組織勢力，GM必須告知你存在。 你可以知道【策士等級／３】個登場人物的完整情報。
A44: 真偽莫辨 | B44: 常時 | C44: - | D44: 0 | E44: 佈局、策士等級三以上 | F44: 你的「佈局」效果增加： 每兩點數值可以讓你製造一個沒有任何實際效果的物品。 製造出來的物品可以是既存已知的物品，除了沒有實際效果外，與真品一模一樣。
...

Sheet 忍者
A1: 忍者
A2: 能力基本值
A3: 體力 | B3: 知覺 | C3: 理智 | D3: 意志
A4: 3 | B4: 3 | C4: 3 | D4: 3
A6: 級別修正表
A7: 等級 | B7: 1 | C7: 2 | D7: 3 | E7: 4 | F7: 5 | G7: 6 | H7: 7 | I7: 8 | J7: 9 | K7: 10
A8: 【近戰】 | B8: 1 | C8: 2 | D8: 3 | E8: 4 | F8: 5 | G8: 6 | H8: 7 | I8: 8 | J8: 9 | K8: 10
A9: 【射撃】 | B9: 1 | C9: 2 | D9: 3 | E9: 4 | F9: 5 | G9: 6 | H9: 7 | I9: 8 | J9: 9 | K9: 10
A10: 【精神】 | B10: 1 | C10: 2 | D10: 3 | E10: 4 | F10: 5 | G10: 6 | H10: 7 | I10: 8 | J10: 9 | K10: 10
A11: 【行動】 | B11: 1 | C11: 2 | D11: 3 | E11: 4 | F11: 5 | G11: 6 | H11: 7 | I11: 8 | J11: 9 | K11: 10
A12: 【生命力】 | B12: -10 | C12: -5 | D12: 0 | E12: 2 | F12: 4 | G12: 6 | H12: 8 | I12: 10 | J12: 12 | K12: 14
A13: 【集中力】 | B13: -10 | C13: -5 | D13: 0 | E13: 2 | F13: 4 | G13: 6 | H13: 8 | I13: 10 | J13: 12 | K13: 14
A14: 【防御點】 | B14: 0 | C14: 0 | D14: 0 | E14: 0 | F14: 0 | G14: 0 | H14: 0 | I14: 0 | J14: 0 | K14: 0
A16: 取得特技 ▲
A17: 初期取得：
A18: 獲得「忍者八門」，然後再選擇一個自己喜歡的特技。
A20: 升級：
A21: 等級上升之時、選取一個喜歡的特技。每逢５等、１０等時，可以額外再取得一個特技。
A23: 技能名稱 | B23: 分類 | C23: 代價 | D23: 情緒獎勵 | E23: 取得限制 | F23: 效果
A24: 忍者
A25: 一般特技 ▲
A26: 忍者八門 | B26: 常時 | C26: - | D26: 0 | E26: 無 | F26: 你身為忍者的資格，會隨著等級變化。 等級一到三：下忍 你空手的傷害成為2D6。 你空手的攻擊類型可成為遠戰。 在透過交談搜尋情報時獲得+《2》修正。 你獲得〔忍者等級Ｘ8〕的溘鎢斯，每日結束時恢復三分之一。溘鎢斯可以視同集中力使用。 劇本開始你獲得一忍具。 等級四到六：中忍 你空手的傷害成為2D6+《忍者等級》。 劇本開始你獲得一忍具。 在逃跑與撤退獲得+《3》修正。 等級七以上：上忍 劇本開始你獲得一忍具。 你忍者相關技能《》內的值+1。 在隱藏氣息獲得+《3》修正。
A27: 霞身術 | B27: 常時 | C27: - | D27: 0 | E27: 下忍 | F27: 習得此技能時，指定一種異常狀態。你將不會被此異常狀態影響。
A28: 偽裝 | B28: 常時 | C28: - | D28: 0 | E28: 下忍 | F28: 劇本開始時，你可設定一個虛構的外貌身分，並擲2D6+《你的忍者等級》作為偽裝基準值。你對未識破你偽裝的人進行偷襲時，成功判定加《你的忍者等級》。識破判定為對方的理智對抗你基準值。
A29: 忍具所持 | B29: 常時 | C29: - | D29: 0 | E29: 下忍 | F29: 劇本開始前，選擇持有一種忍具。
A30: 影縫 | B30: 進攻／遠戰 | C30: 苦無任意數目(不可為零)，代價傷害5點 | D30: 0 | E30: 中忍 | F30: 命中即給予對手不良狀態「麻痺」。 此次攻擊的命中+《代價苦無數目》。 此不良狀態持續一回合。
A31: 隱劍五方投 | B31: 攻擊類型/遠戰 | C31: 手裏劍1、代價傷害10 | D31: 0 | E31: 中忍 | F31: 給予一對手3D6+【你忍者等級】的傷害。 此次攻擊的命中+5。
A32: 忍術‧自在變化 | B32: 準備階段 | C32: 代價傷害10 | D32: 0 | E32: 中忍 | F32: 可重新調配近戰、射擊、精神、行動四者數值，但不得為負數。調整數值增減不得超過你的【忍者等級】。
A33: 土之道 | B33: 準備階段 | C33: - | D33: 0 | E33: 下忍 | F33: 你進入「潛行」狀態。你可以無視阻礙移動。每次輪到你行動時，需與其他人進行潛行判定(GM視狀況決定雙方使用何種能力判定)，對象判定失敗時，你對對象的迴避與命中增加《你的忍者等級》。
A34: 水之道 | B34: 通用 | C34: 行動點10 | D34: 0 | E34: 下忍 | F34: 1.當你受到近戰攻擊時，可以直接相殺。 2.當你進行完攻擊時，每使用一次這技能，增加一次額外的空手攻擊判定(無法附加進攻技能，但受常駐能力影響)
A35: 風之道 | B35: 常時 | C35: - | D35: 0 | E35: 下忍 | F35: 你使用忍具進行的攻擊，命中額外增加《你的忍者等級》。你在逃跑上的判定增加《現在回合數》。
A36: 火之道 | B36: 常時 | C36: - | D36: 0 | E36: 下忍 | F36: 你使用忍具進行的攻擊，傷害額外增加《你的忍者等級》。當你進行迴避判定時，每消耗一忍具，增加迴避判定一點。
A37: 空 | B37: 常時 | C37: - | D37: 0 | E37: 土之道、水之道、火之道、風之道 | F37: 你額外獲得【忍者等級】X2的溘鎢斯，每日結束後自動補充至最大值。 你可以在攻擊上附加溘鎢斯，每五點溘鎢斯，增加1D6傷害。 你可以在迴避上附加溘鎢斯，每十點溘鎢斯，增加1D6判定。 你可以使用溘鎢斯恢復體能狀況，每五點溘鎢斯，恢復1D6。 你使用忍捲召喚之靈，全能力增加《你的忍者等級》。
... A41: 秘忍術‧八門煉化 | B41: 常時 | C41: - | D41: 0 | E41: 上忍 | F41: 在你受到【死亡】的一擊時，可以從場景消失並復活，血量恢復至你的殘存溘鎢斯值(最低為1)。 在劇本結束前，全判定上升三。 此技能一劇本只會發動一次。

Sheet 無名劍
A1: 無名劍
A2: 能力基本值
A3: 體力 | B3: 知覺 | C3: 理智 | D3: 意志
A4: 2 | B4: 4 | C4: 2 | D4: 4
A6: 級別修正表
A7: 等級 | B7: 1 | C7: 2 | D7: 3 | E7: 4 | F7: 5 | G7: 6 | H7: 7 | I7: 8 | J7: 9 | K7: 10
A8: 【近戰】 | B8: -1 | C8: 0 | D8: 1 | E8: 3 | F8: 5 | G8: 7 | H8: 9 | I8: 10 | J8: 11 | K8: 12
A9: 【射撃】 | B9: 0 | C9: 0 | D9: 1 | E9: 2 | F9: 3 | G9: 4 | H9: 5 | I9: 6 | J9: 7 | K9: 8
A10: 【精神】 | B10: 0 | C10: 0 | D10: 1 | E10: 2 | F10: 3 | G10: 4 | H10: 5 | I10: 6 | J10: 7 | K10: 8
A11: 【行動】 | B11: 0 | C11: 1 | D11: 2 | E11: 5 | F11: 8 | G11: 11 | H11: 13 | I11: 14 | J11: 15 | K11: 16
A12: 【生命力】 | B12: 0 | C12: 3 | D12: 6 | E12: 9 | F12: 16 | G12: 19 | H12: 22 | I12: 25 | J12: 28 | K12: 31
A13: 【集中力】 | B13: 0 | C13: 3 | D13: 6 | E13: 9 | F13: 12 | G13: 15 | H13: 18 | I13: 21 | J13: 24 | K13: 27
A14: 【防御點】 | B14: 0 | C14: 0 | D14: 0 | E14: 0 | F14: 1 | G14: 1 | H14: 1 | I14: 1 | J14: 1 | K14: 2
A16: 取得特技 ▲
A17: 初期取得：
A18: 得到「無名之劍」，然後再選擇一個自己喜歡的特技。
A20: 升級：
A21: 等級上升之時、選取一個喜歡的特技。每逢５等、１０等時，可以額外再取得一個特技。
A23: 技能名稱 | B23: 分類 | C23: 代價 | D23: 情緒獎勵 | E23: 取得限制 | F23: 效果
A24: 無名劍
A25: 一般特技 ▲
A26: 無名之劍 | B26: 常時 | C26: - | D26: 0 | E26: 無 | F26: 你在劇本開始時得到【你的無名劍等級】個Cost。 你能常時擁有的Cost上限為【你的無名劍等級】+1。超過的在場景終了時捨去。 你每持有1個Cost傷害+1，每3個命中和迴避+1。 戰鬥以外時，每花費代價傷害十點，可以恢復一個Cost。
A27: 〈彌生〉彌生 | B27: 常時／準備階段 | C27: 代價傷害15 | D27: 0 | E27: 無 | F27: 每個場景開始時，Cost低於3則得到【無名劍等級／3】Cost，無法因為這個技能讓Cost超過3個。 準備階段使用，戰鬥終了前每個準備階段得到1個Cost。
A28: 〈睦月〉年端 | B28: 攻擊類型／近戰 | C28: - | D28: 2 | E28: 無 | F28: 指定對象一人，給予２Ｄ６傷害。 一戰鬥一回，追加2個Cost，命中達成值為2倍；追加4個Cost，傷害為2倍。 複數攻擊的情形，選擇一次攻擊得到Cost追加的效果。
A29: 〈長月〉殘月 | B29: 攻擊類型／近戰 | C29: - | D29: 2 | E29: 無 | F29: 指定一個對象給予1D6+【無名劍等級】點傷害。 每持有1個Cost傷害就可以+1。 以這個特技給予對象致死的攻擊後，得到《15》點情緒值。
